{
 "cells": [
  {
   "cell_type": "code",
   "execution_count": 15,
   "metadata": {},
   "outputs": [],
   "source": [
    "import pandas as pd\n",
    "import numpy as np\n",
    "\n",
    "from sklearn.model_selection import StratifiedKFold\n",
    "from sklearn.model_selection import GridSearchCV\n",
    "from sklearn.model_selection import train_test_split\n",
    "\n",
    "from time import time\n",
    "import pprint\n",
    "import joblib\n",
    "import warnings\n",
    "import sklearn\n",
    "\n",
    "from catboost import CatBoostClassifier\n",
    "\n",
    "from sklearn.metrics import roc_auc_score\n",
    "from sklearn.metrics import mean_squared_error as mse \n",
    "from sklearn.metrics import make_scorer\n",
    "\n",
    "from skopt import BayesSearchCV\n",
    "from skopt.callbacks import DeadlineStopper, VerboseCallback, DeltaXStopper\n",
    "from skopt.space import Real, Categorical, Integer"
   ]
  },
  {
   "cell_type": "code",
   "execution_count": 16,
   "metadata": {},
   "outputs": [],
   "source": [
    "df = pd.read_csv('../../datasets/loan_data_clean.csv')"
   ]
  },
  {
   "cell_type": "code",
   "execution_count": 17,
   "metadata": {},
   "outputs": [
    {
     "data": {
      "text/html": [
       "<div>\n",
       "<style scoped>\n",
       "    .dataframe tbody tr th:only-of-type {\n",
       "        vertical-align: middle;\n",
       "    }\n",
       "\n",
       "    .dataframe tbody tr th {\n",
       "        vertical-align: top;\n",
       "    }\n",
       "\n",
       "    .dataframe thead th {\n",
       "        text-align: right;\n",
       "    }\n",
       "</style>\n",
       "<table border=\"1\" class=\"dataframe\">\n",
       "  <thead>\n",
       "    <tr style=\"text-align: right;\">\n",
       "      <th></th>\n",
       "      <th>Unnamed: 0</th>\n",
       "      <th>Gender</th>\n",
       "      <th>Married</th>\n",
       "      <th>Dependents</th>\n",
       "      <th>Education</th>\n",
       "      <th>Self_Employed</th>\n",
       "      <th>ApplicantIncome</th>\n",
       "      <th>CoapplicantIncome</th>\n",
       "      <th>LoanAmount</th>\n",
       "      <th>Loan_Amount_Term</th>\n",
       "      <th>Credit_History</th>\n",
       "      <th>Property_Area</th>\n",
       "      <th>Loan_Status</th>\n",
       "    </tr>\n",
       "  </thead>\n",
       "  <tbody>\n",
       "    <tr>\n",
       "      <th>0</th>\n",
       "      <td>0</td>\n",
       "      <td>1</td>\n",
       "      <td>0</td>\n",
       "      <td>0.0</td>\n",
       "      <td>0</td>\n",
       "      <td>0</td>\n",
       "      <td>376</td>\n",
       "      <td>0.0</td>\n",
       "      <td>146.412162</td>\n",
       "      <td>360.0</td>\n",
       "      <td>1.0</td>\n",
       "      <td>2</td>\n",
       "      <td>1</td>\n",
       "    </tr>\n",
       "    <tr>\n",
       "      <th>1</th>\n",
       "      <td>1</td>\n",
       "      <td>1</td>\n",
       "      <td>1</td>\n",
       "      <td>1.0</td>\n",
       "      <td>0</td>\n",
       "      <td>0</td>\n",
       "      <td>306</td>\n",
       "      <td>1508.0</td>\n",
       "      <td>128.000000</td>\n",
       "      <td>360.0</td>\n",
       "      <td>1.0</td>\n",
       "      <td>0</td>\n",
       "      <td>0</td>\n",
       "    </tr>\n",
       "    <tr>\n",
       "      <th>2</th>\n",
       "      <td>2</td>\n",
       "      <td>1</td>\n",
       "      <td>1</td>\n",
       "      <td>0.0</td>\n",
       "      <td>0</td>\n",
       "      <td>1</td>\n",
       "      <td>139</td>\n",
       "      <td>0.0</td>\n",
       "      <td>66.000000</td>\n",
       "      <td>360.0</td>\n",
       "      <td>1.0</td>\n",
       "      <td>2</td>\n",
       "      <td>1</td>\n",
       "    </tr>\n",
       "    <tr>\n",
       "      <th>3</th>\n",
       "      <td>3</td>\n",
       "      <td>1</td>\n",
       "      <td>1</td>\n",
       "      <td>0.0</td>\n",
       "      <td>1</td>\n",
       "      <td>0</td>\n",
       "      <td>90</td>\n",
       "      <td>2358.0</td>\n",
       "      <td>120.000000</td>\n",
       "      <td>360.0</td>\n",
       "      <td>1.0</td>\n",
       "      <td>2</td>\n",
       "      <td>1</td>\n",
       "    </tr>\n",
       "    <tr>\n",
       "      <th>4</th>\n",
       "      <td>4</td>\n",
       "      <td>1</td>\n",
       "      <td>0</td>\n",
       "      <td>0.0</td>\n",
       "      <td>0</td>\n",
       "      <td>0</td>\n",
       "      <td>381</td>\n",
       "      <td>0.0</td>\n",
       "      <td>141.000000</td>\n",
       "      <td>360.0</td>\n",
       "      <td>1.0</td>\n",
       "      <td>2</td>\n",
       "      <td>1</td>\n",
       "    </tr>\n",
       "    <tr>\n",
       "      <th>...</th>\n",
       "      <td>...</td>\n",
       "      <td>...</td>\n",
       "      <td>...</td>\n",
       "      <td>...</td>\n",
       "      <td>...</td>\n",
       "      <td>...</td>\n",
       "      <td>...</td>\n",
       "      <td>...</td>\n",
       "      <td>...</td>\n",
       "      <td>...</td>\n",
       "      <td>...</td>\n",
       "      <td>...</td>\n",
       "      <td>...</td>\n",
       "    </tr>\n",
       "    <tr>\n",
       "      <th>609</th>\n",
       "      <td>609</td>\n",
       "      <td>0</td>\n",
       "      <td>0</td>\n",
       "      <td>0.0</td>\n",
       "      <td>0</td>\n",
       "      <td>0</td>\n",
       "      <td>125</td>\n",
       "      <td>0.0</td>\n",
       "      <td>71.000000</td>\n",
       "      <td>360.0</td>\n",
       "      <td>1.0</td>\n",
       "      <td>0</td>\n",
       "      <td>1</td>\n",
       "    </tr>\n",
       "    <tr>\n",
       "      <th>610</th>\n",
       "      <td>610</td>\n",
       "      <td>1</td>\n",
       "      <td>1</td>\n",
       "      <td>3.0</td>\n",
       "      <td>0</td>\n",
       "      <td>0</td>\n",
       "      <td>275</td>\n",
       "      <td>0.0</td>\n",
       "      <td>40.000000</td>\n",
       "      <td>180.0</td>\n",
       "      <td>1.0</td>\n",
       "      <td>0</td>\n",
       "      <td>1</td>\n",
       "    </tr>\n",
       "    <tr>\n",
       "      <th>611</th>\n",
       "      <td>611</td>\n",
       "      <td>1</td>\n",
       "      <td>1</td>\n",
       "      <td>1.0</td>\n",
       "      <td>0</td>\n",
       "      <td>0</td>\n",
       "      <td>431</td>\n",
       "      <td>240.0</td>\n",
       "      <td>253.000000</td>\n",
       "      <td>360.0</td>\n",
       "      <td>1.0</td>\n",
       "      <td>2</td>\n",
       "      <td>1</td>\n",
       "    </tr>\n",
       "    <tr>\n",
       "      <th>612</th>\n",
       "      <td>612</td>\n",
       "      <td>1</td>\n",
       "      <td>1</td>\n",
       "      <td>2.0</td>\n",
       "      <td>0</td>\n",
       "      <td>0</td>\n",
       "      <td>422</td>\n",
       "      <td>0.0</td>\n",
       "      <td>187.000000</td>\n",
       "      <td>360.0</td>\n",
       "      <td>1.0</td>\n",
       "      <td>2</td>\n",
       "      <td>1</td>\n",
       "    </tr>\n",
       "    <tr>\n",
       "      <th>613</th>\n",
       "      <td>613</td>\n",
       "      <td>0</td>\n",
       "      <td>0</td>\n",
       "      <td>0.0</td>\n",
       "      <td>0</td>\n",
       "      <td>1</td>\n",
       "      <td>306</td>\n",
       "      <td>0.0</td>\n",
       "      <td>133.000000</td>\n",
       "      <td>360.0</td>\n",
       "      <td>0.0</td>\n",
       "      <td>1</td>\n",
       "      <td>0</td>\n",
       "    </tr>\n",
       "  </tbody>\n",
       "</table>\n",
       "<p>614 rows Ã— 13 columns</p>\n",
       "</div>"
      ],
      "text/plain": [
       "     Unnamed: 0  Gender  Married  Dependents  Education  Self_Employed  \\\n",
       "0             0       1        0         0.0          0              0   \n",
       "1             1       1        1         1.0          0              0   \n",
       "2             2       1        1         0.0          0              1   \n",
       "3             3       1        1         0.0          1              0   \n",
       "4             4       1        0         0.0          0              0   \n",
       "..          ...     ...      ...         ...        ...            ...   \n",
       "609         609       0        0         0.0          0              0   \n",
       "610         610       1        1         3.0          0              0   \n",
       "611         611       1        1         1.0          0              0   \n",
       "612         612       1        1         2.0          0              0   \n",
       "613         613       0        0         0.0          0              1   \n",
       "\n",
       "     ApplicantIncome  CoapplicantIncome  LoanAmount  Loan_Amount_Term  \\\n",
       "0                376                0.0  146.412162             360.0   \n",
       "1                306             1508.0  128.000000             360.0   \n",
       "2                139                0.0   66.000000             360.0   \n",
       "3                 90             2358.0  120.000000             360.0   \n",
       "4                381                0.0  141.000000             360.0   \n",
       "..               ...                ...         ...               ...   \n",
       "609              125                0.0   71.000000             360.0   \n",
       "610              275                0.0   40.000000             180.0   \n",
       "611              431              240.0  253.000000             360.0   \n",
       "612              422                0.0  187.000000             360.0   \n",
       "613              306                0.0  133.000000             360.0   \n",
       "\n",
       "     Credit_History  Property_Area  Loan_Status  \n",
       "0               1.0              2            1  \n",
       "1               1.0              0            0  \n",
       "2               1.0              2            1  \n",
       "3               1.0              2            1  \n",
       "4               1.0              2            1  \n",
       "..              ...            ...          ...  \n",
       "609             1.0              0            1  \n",
       "610             1.0              0            1  \n",
       "611             1.0              2            1  \n",
       "612             1.0              2            1  \n",
       "613             0.0              1            0  \n",
       "\n",
       "[614 rows x 13 columns]"
      ]
     },
     "execution_count": 17,
     "metadata": {},
     "output_type": "execute_result"
    }
   ],
   "source": [
    "df"
   ]
  },
  {
   "cell_type": "code",
   "execution_count": 18,
   "metadata": {},
   "outputs": [
    {
     "data": {
      "text/plain": [
       "Index(['Unnamed: 0', 'Gender', 'Married', 'Dependents', 'Education',\n",
       "       'Self_Employed', 'ApplicantIncome', 'CoapplicantIncome', 'LoanAmount',\n",
       "       'Loan_Amount_Term', 'Credit_History', 'Property_Area', 'Loan_Status'],\n",
       "      dtype='object')"
      ]
     },
     "execution_count": 18,
     "metadata": {},
     "output_type": "execute_result"
    }
   ],
   "source": [
    "df.columns"
   ]
  },
  {
   "cell_type": "code",
   "execution_count": 19,
   "metadata": {},
   "outputs": [],
   "source": [
    "x_cols = ['Gender', 'Married', 'Dependents', 'Education',\n",
    "       'Self_Employed', 'ApplicantIncome', 'CoapplicantIncome', 'LoanAmount',\n",
    "       'Loan_Amount_Term', 'Credit_History', 'Property_Area']\n",
    "\n",
    "x = df[x_cols]\n",
    "y = df['Loan_Status']"
   ]
  },
  {
   "cell_type": "code",
   "execution_count": 20,
   "metadata": {},
   "outputs": [],
   "source": [
    "x_train, x_validate, y_train, y_validate = train_test_split(x, y, test_size=0.3, random_state=12)"
   ]
  },
  {
   "cell_type": "code",
   "execution_count": 21,
   "metadata": {},
   "outputs": [
    {
     "data": {
      "text/plain": [
       "<catboost.core.CatBoostClassifier at 0x20629049670>"
      ]
     },
     "execution_count": 21,
     "metadata": {},
     "output_type": "execute_result"
    }
   ],
   "source": [
    "#basemodel\n",
    "bs_mdl = CatBoostClassifier(task_type='CPU', verbose=False)\n",
    "\n",
    "bs_mdl.fit(x_train, y_train)"
   ]
  },
  {
   "cell_type": "code",
   "execution_count": 22,
   "metadata": {},
   "outputs": [
    {
     "data": {
      "text/plain": [
       "0.3991951342493785"
      ]
     },
     "execution_count": 22,
     "metadata": {},
     "output_type": "execute_result"
    }
   ],
   "source": [
    "y_pred = bs_mdl.predict_proba(x_validate)[:, 1]\n",
    "score  = np.sqrt(mse(y_validate, y_pred))\n",
    "score"
   ]
  },
  {
   "cell_type": "code",
   "execution_count": 23,
   "metadata": {},
   "outputs": [],
   "source": [
    "#Bayes optimizer\n",
    "\n",
    "def performance_report(optimizer, x, y, title, callbacks=None):\n",
    "    \n",
    "    start = time()\n",
    "    \n",
    "    if callbacks:\n",
    "        optimizer.fit(x, y, callbacks=callbacks)\n",
    "    else:\n",
    "        optimizer.fit(x, y)\n",
    "        \n",
    "    d = pd.DataFrame(optimizer.cv_results_)\n",
    "    best_score = optimizer.best_score_\n",
    "    best_score_std = d.iloc[optimizer.best_index_].std_test_score\n",
    "    best_params = optimizer.best_params_\n",
    "    \n",
    "    print((title + ' took %.2f seconds, candidates checked: %d, best CV score: %.3f' +u'\\u00B1'+'%.3f') % (time() - start, \n",
    "                                                                                                          len(optimizer.cv_results_['params']),\n",
    "                                                                                                          best_score,\n",
    "                                                                                                          best_score_std))\n",
    "    print('Best Parameters: ')\n",
    "    pprint.pprint(best_params)\n",
    "    \n",
    "    \n",
    "    return best_params"
   ]
  },
  {
   "cell_type": "code",
   "execution_count": 24,
   "metadata": {},
   "outputs": [],
   "source": [
    "roc_auc = make_scorer(roc_auc_score, greater_is_better=True, needs_threshold=True)\n",
    "\n",
    "skf = StratifiedKFold(n_splits=5, shuffle=True, random_state=0)"
   ]
  },
  {
   "cell_type": "code",
   "execution_count": 25,
   "metadata": {},
   "outputs": [],
   "source": [
    "clf = CatBoostClassifier(thread_count=2,\n",
    "                         loss_function='Logloss',\n",
    "                         od_type='Iter',\n",
    "                         verbose=False)"
   ]
  },
  {
   "cell_type": "code",
   "execution_count": 26,
   "metadata": {},
   "outputs": [],
   "source": [
    "baye_space = {\n",
    "    'iterations': Integer(10, 1000), \n",
    "    'depth' : Integer(1, 8),\n",
    "    'learning_rate' : Real(0.01, 1.0, 'log-uniform'),\n",
    "    'random_strength' : Real(1e-9, 10, 'log-uniform'),\n",
    "    'bagging_temperature' : Real(0.0, 1.0),\n",
    "    'border_count' : Integer(1, 255), \n",
    "    #'12_leaf_reg' : Integer(2, 30), \n",
    "    'scale_pos_weight' : Real(0.01, 1.0, 'uniform')\n",
    "}"
   ]
  },
  {
   "cell_type": "code",
   "execution_count": 27,
   "metadata": {},
   "outputs": [],
   "source": [
    "opt = BayesSearchCV(\n",
    "    clf, \n",
    "    baye_space,\n",
    "    cv = skf,\n",
    "    n_iter = 100,\n",
    "    n_jobs=1,\n",
    "    return_train_score=False, \n",
    "    refit=True,\n",
    "    optimizer_kwargs={'base_estimator' : 'GP'},\n",
    "    random_state=42\n",
    ")"
   ]
  },
  {
   "cell_type": "code",
   "execution_count": 28,
   "metadata": {},
   "outputs": [
    {
     "name": "stdout",
     "output_type": "stream",
     "text": [
      "Iteration No: 1 started. Searching for the next optimal point.\n"
     ]
    },
    {
     "ename": "SystemError",
     "evalue": "<method '_train' of '_catboost._CatBoost' objects> returned a result with an error set",
     "output_type": "error",
     "traceback": [
      "\u001b[1;31m---------------------------------------------------------------------------\u001b[0m",
      "\u001b[1;31mAttributeError\u001b[0m                            Traceback (most recent call last)",
      "\u001b[1;32m_catboost.pyx\u001b[0m in \u001b[0;36m_catboost._CallbackAfterIteration\u001b[1;34m()\u001b[0m\n",
      "\u001b[1;32m~\\AppData\\Local\\Packages\\PythonSoftwareFoundation.Python.3.9_qbz5n2kfra8p0\\LocalCache\\local-packages\\Python39\\site-packages\\catboost\\core.py\u001b[0m in \u001b[0;36mafter_iteration\u001b[1;34m(self, info)\u001b[0m\n\u001b[0;32m   6699\u001b[0m         \u001b[1;32mfor\u001b[0m \u001b[0mcb\u001b[0m \u001b[1;32min\u001b[0m \u001b[0mself\u001b[0m\u001b[1;33m.\u001b[0m\u001b[0m_callbacks\u001b[0m\u001b[1;33m:\u001b[0m\u001b[1;33m\u001b[0m\u001b[1;33m\u001b[0m\u001b[0m\n\u001b[1;32m-> 6700\u001b[1;33m             \u001b[1;32mif\u001b[0m \u001b[1;32mnot\u001b[0m \u001b[0mcb\u001b[0m\u001b[1;33m.\u001b[0m\u001b[0mafter_iteration\u001b[0m\u001b[1;33m(\u001b[0m\u001b[0minfo\u001b[0m\u001b[1;33m)\u001b[0m\u001b[1;33m:\u001b[0m\u001b[1;33m\u001b[0m\u001b[1;33m\u001b[0m\u001b[0m\n\u001b[0m\u001b[0;32m   6701\u001b[0m                 \u001b[1;32mreturn\u001b[0m \u001b[1;32mFalse\u001b[0m\u001b[1;33m\u001b[0m\u001b[1;33m\u001b[0m\u001b[0m\n",
      "\u001b[1;31mAttributeError\u001b[0m: 'VerboseCallback' object has no attribute 'after_iteration'",
      "\nThe above exception was the direct cause of the following exception:\n",
      "\u001b[1;31mSystemError\u001b[0m                               Traceback (most recent call last)",
      "\u001b[1;32m_catboost.pyx\u001b[0m in \u001b[0;36m_catboost._CallbackAfterIteration\u001b[1;34m()\u001b[0m\n",
      "\u001b[1;31mSystemError\u001b[0m: <class 'types.SimpleNamespace'> returned a result with an error set",
      "\nThe above exception was the direct cause of the following exception:\n",
      "\u001b[1;31mSystemError\u001b[0m                               Traceback (most recent call last)",
      "\u001b[1;32m_catboost.pyx\u001b[0m in \u001b[0;36m_catboost._CallbackAfterIteration\u001b[1;34m()\u001b[0m\n",
      "\u001b[1;31mSystemError\u001b[0m: <class 'types.SimpleNamespace'> returned a result with an error set",
      "\nThe above exception was the direct cause of the following exception:\n",
      "\u001b[1;31mSystemError\u001b[0m                               Traceback (most recent call last)",
      "\u001b[1;32m_catboost.pyx\u001b[0m in \u001b[0;36m_catboost._CallbackAfterIteration\u001b[1;34m()\u001b[0m\n",
      "\u001b[1;31mSystemError\u001b[0m: <class 'types.SimpleNamespace'> returned a result with an error set",
      "\nThe above exception was the direct cause of the following exception:\n",
      "\u001b[1;31mSystemError\u001b[0m                               Traceback (most recent call last)",
      "\u001b[1;32m_catboost.pyx\u001b[0m in \u001b[0;36m_catboost._CallbackAfterIteration\u001b[1;34m()\u001b[0m\n",
      "\u001b[1;31mSystemError\u001b[0m: <class 'types.SimpleNamespace'> returned a result with an error set",
      "\nThe above exception was the direct cause of the following exception:\n",
      "\u001b[1;31mSystemError\u001b[0m                               Traceback (most recent call last)",
      "\u001b[1;32m_catboost.pyx\u001b[0m in \u001b[0;36m_catboost._CallbackAfterIteration\u001b[1;34m()\u001b[0m\n",
      "\u001b[1;31mSystemError\u001b[0m: <class 'types.SimpleNamespace'> returned a result with an error set",
      "\nThe above exception was the direct cause of the following exception:\n",
      "\u001b[1;31mSystemError\u001b[0m                               Traceback (most recent call last)",
      "\u001b[1;32m_catboost.pyx\u001b[0m in \u001b[0;36m_catboost._CallbackAfterIteration\u001b[1;34m()\u001b[0m\n",
      "\u001b[1;31mSystemError\u001b[0m: <class 'types.SimpleNamespace'> returned a result with an error set",
      "\nThe above exception was the direct cause of the following exception:\n",
      "\u001b[1;31mSystemError\u001b[0m                               Traceback (most recent call last)",
      "\u001b[1;32m_catboost.pyx\u001b[0m in \u001b[0;36m_catboost._CallbackAfterIteration\u001b[1;34m()\u001b[0m\n",
      "\u001b[1;31mSystemError\u001b[0m: <class 'types.SimpleNamespace'> returned a result with an error set",
      "\nThe above exception was the direct cause of the following exception:\n",
      "\u001b[1;31mSystemError\u001b[0m                               Traceback (most recent call last)",
      "\u001b[1;32m_catboost.pyx\u001b[0m in \u001b[0;36m_catboost._CallbackAfterIteration\u001b[1;34m()\u001b[0m\n",
      "\u001b[1;31mSystemError\u001b[0m: <class 'types.SimpleNamespace'> returned a result with an error set",
      "\nThe above exception was the direct cause of the following exception:\n",
      "\u001b[1;31mSystemError\u001b[0m                               Traceback (most recent call last)",
      "\u001b[1;32m_catboost.pyx\u001b[0m in \u001b[0;36m_catboost._CallbackAfterIteration\u001b[1;34m()\u001b[0m\n",
      "\u001b[1;31mSystemError\u001b[0m: <class 'types.SimpleNamespace'> returned a result with an error set",
      "\nThe above exception was the direct cause of the following exception:\n",
      "\u001b[1;31mSystemError\u001b[0m                               Traceback (most recent call last)",
      "\u001b[1;32m_catboost.pyx\u001b[0m in \u001b[0;36m_catboost._CallbackAfterIteration\u001b[1;34m()\u001b[0m\n",
      "\u001b[1;31mSystemError\u001b[0m: <class 'types.SimpleNamespace'> returned a result with an error set",
      "\nThe above exception was the direct cause of the following exception:\n",
      "\u001b[1;31mSystemError\u001b[0m                               Traceback (most recent call last)",
      "\u001b[1;32m_catboost.pyx\u001b[0m in \u001b[0;36m_catboost._CallbackAfterIteration\u001b[1;34m()\u001b[0m\n",
      "\u001b[1;31mSystemError\u001b[0m: <class 'types.SimpleNamespace'> returned a result with an error set",
      "\nThe above exception was the direct cause of the following exception:\n",
      "\u001b[1;31mSystemError\u001b[0m                               Traceback (most recent call last)",
      "\u001b[1;32m_catboost.pyx\u001b[0m in \u001b[0;36m_catboost._CallbackAfterIteration\u001b[1;34m()\u001b[0m\n",
      "\u001b[1;31mSystemError\u001b[0m: <class 'types.SimpleNamespace'> returned a result with an error set",
      "\nThe above exception was the direct cause of the following exception:\n",
      "\u001b[1;31mSystemError\u001b[0m                               Traceback (most recent call last)",
      "\u001b[1;32m_catboost.pyx\u001b[0m in \u001b[0;36m_catboost._CallbackAfterIteration\u001b[1;34m()\u001b[0m\n",
      "\u001b[1;31mSystemError\u001b[0m: <class 'types.SimpleNamespace'> returned a result with an error set",
      "\nThe above exception was the direct cause of the following exception:\n",
      "\u001b[1;31mSystemError\u001b[0m                               Traceback (most recent call last)",
      "\u001b[1;32m_catboost.pyx\u001b[0m in \u001b[0;36m_catboost._CallbackAfterIteration\u001b[1;34m()\u001b[0m\n",
      "\u001b[1;31mSystemError\u001b[0m: <class 'types.SimpleNamespace'> returned a result with an error set",
      "\nThe above exception was the direct cause of the following exception:\n",
      "\u001b[1;31mSystemError\u001b[0m                               Traceback (most recent call last)",
      "\u001b[1;32m_catboost.pyx\u001b[0m in \u001b[0;36m_catboost._CallbackAfterIteration\u001b[1;34m()\u001b[0m\n",
      "\u001b[1;31mSystemError\u001b[0m: <class 'types.SimpleNamespace'> returned a result with an error set",
      "\nThe above exception was the direct cause of the following exception:\n",
      "\u001b[1;31mSystemError\u001b[0m                               Traceback (most recent call last)",
      "\u001b[1;32m_catboost.pyx\u001b[0m in \u001b[0;36m_catboost._CallbackAfterIteration\u001b[1;34m()\u001b[0m\n",
      "\u001b[1;31mSystemError\u001b[0m: <class 'types.SimpleNamespace'> returned a result with an error set",
      "\nThe above exception was the direct cause of the following exception:\n",
      "\u001b[1;31mSystemError\u001b[0m                               Traceback (most recent call last)",
      "\u001b[1;32m_catboost.pyx\u001b[0m in \u001b[0;36m_catboost._CallbackAfterIteration\u001b[1;34m()\u001b[0m\n",
      "\u001b[1;31mSystemError\u001b[0m: <class 'types.SimpleNamespace'> returned a result with an error set",
      "\nThe above exception was the direct cause of the following exception:\n",
      "\u001b[1;31mSystemError\u001b[0m                               Traceback (most recent call last)",
      "\u001b[1;32m_catboost.pyx\u001b[0m in \u001b[0;36m_catboost._CallbackAfterIteration\u001b[1;34m()\u001b[0m\n",
      "\u001b[1;31mSystemError\u001b[0m: <class 'types.SimpleNamespace'> returned a result with an error set",
      "\nThe above exception was the direct cause of the following exception:\n",
      "\u001b[1;31mSystemError\u001b[0m                               Traceback (most recent call last)",
      "\u001b[1;32m_catboost.pyx\u001b[0m in \u001b[0;36m_catboost._CallbackAfterIteration\u001b[1;34m()\u001b[0m\n",
      "\u001b[1;31mSystemError\u001b[0m: <class 'types.SimpleNamespace'> returned a result with an error set",
      "\nThe above exception was the direct cause of the following exception:\n",
      "\u001b[1;31mSystemError\u001b[0m                               Traceback (most recent call last)",
      "\u001b[1;32m_catboost.pyx\u001b[0m in \u001b[0;36m_catboost._CallbackAfterIteration\u001b[1;34m()\u001b[0m\n",
      "\u001b[1;31mSystemError\u001b[0m: <class 'types.SimpleNamespace'> returned a result with an error set",
      "\nThe above exception was the direct cause of the following exception:\n",
      "\u001b[1;31mSystemError\u001b[0m                               Traceback (most recent call last)",
      "\u001b[1;32m_catboost.pyx\u001b[0m in \u001b[0;36m_catboost._CallbackAfterIteration\u001b[1;34m()\u001b[0m\n",
      "\u001b[1;31mSystemError\u001b[0m: <class 'types.SimpleNamespace'> returned a result with an error set",
      "\nThe above exception was the direct cause of the following exception:\n",
      "\u001b[1;31mSystemError\u001b[0m                               Traceback (most recent call last)",
      "\u001b[1;32m_catboost.pyx\u001b[0m in \u001b[0;36m_catboost._CallbackAfterIteration\u001b[1;34m()\u001b[0m\n",
      "\u001b[1;31mSystemError\u001b[0m: <class 'types.SimpleNamespace'> returned a result with an error set",
      "\nThe above exception was the direct cause of the following exception:\n",
      "\u001b[1;31mSystemError\u001b[0m                               Traceback (most recent call last)",
      "\u001b[1;32m_catboost.pyx\u001b[0m in \u001b[0;36m_catboost._CallbackAfterIteration\u001b[1;34m()\u001b[0m\n",
      "\u001b[1;31mSystemError\u001b[0m: <class 'types.SimpleNamespace'> returned a result with an error set",
      "\nThe above exception was the direct cause of the following exception:\n",
      "\u001b[1;31mSystemError\u001b[0m                               Traceback (most recent call last)",
      "\u001b[1;32m_catboost.pyx\u001b[0m in \u001b[0;36m_catboost._CallbackAfterIteration\u001b[1;34m()\u001b[0m\n",
      "\u001b[1;31mSystemError\u001b[0m: <class 'types.SimpleNamespace'> returned a result with an error set",
      "\nThe above exception was the direct cause of the following exception:\n",
      "\u001b[1;31mSystemError\u001b[0m                               Traceback (most recent call last)",
      "\u001b[1;32m_catboost.pyx\u001b[0m in \u001b[0;36m_catboost._CallbackAfterIteration\u001b[1;34m()\u001b[0m\n",
      "\u001b[1;31mSystemError\u001b[0m: <class 'types.SimpleNamespace'> returned a result with an error set",
      "\nThe above exception was the direct cause of the following exception:\n",
      "\u001b[1;31mSystemError\u001b[0m                               Traceback (most recent call last)",
      "\u001b[1;32m_catboost.pyx\u001b[0m in \u001b[0;36m_catboost._CallbackAfterIteration\u001b[1;34m()\u001b[0m\n",
      "\u001b[1;31mSystemError\u001b[0m: <class 'types.SimpleNamespace'> returned a result with an error set",
      "\nThe above exception was the direct cause of the following exception:\n",
      "\u001b[1;31mSystemError\u001b[0m                               Traceback (most recent call last)",
      "\u001b[1;32m_catboost.pyx\u001b[0m in \u001b[0;36m_catboost._CallbackAfterIteration\u001b[1;34m()\u001b[0m\n",
      "\u001b[1;31mSystemError\u001b[0m: <class 'types.SimpleNamespace'> returned a result with an error set",
      "\nThe above exception was the direct cause of the following exception:\n",
      "\u001b[1;31mSystemError\u001b[0m                               Traceback (most recent call last)",
      "\u001b[1;32m_catboost.pyx\u001b[0m in \u001b[0;36m_catboost._CallbackAfterIteration\u001b[1;34m()\u001b[0m\n",
      "\u001b[1;31mSystemError\u001b[0m: <class 'types.SimpleNamespace'> returned a result with an error set",
      "\nThe above exception was the direct cause of the following exception:\n",
      "\u001b[1;31mSystemError\u001b[0m                               Traceback (most recent call last)",
      "\u001b[1;32m_catboost.pyx\u001b[0m in \u001b[0;36m_catboost._CallbackAfterIteration\u001b[1;34m()\u001b[0m\n",
      "\u001b[1;31mSystemError\u001b[0m: <class 'types.SimpleNamespace'> returned a result with an error set",
      "\nThe above exception was the direct cause of the following exception:\n",
      "\u001b[1;31mSystemError\u001b[0m                               Traceback (most recent call last)",
      "\u001b[1;32m_catboost.pyx\u001b[0m in \u001b[0;36m_catboost._CallbackAfterIteration\u001b[1;34m()\u001b[0m\n",
      "\u001b[1;31mSystemError\u001b[0m: <class 'types.SimpleNamespace'> returned a result with an error set",
      "\nThe above exception was the direct cause of the following exception:\n",
      "\u001b[1;31mSystemError\u001b[0m                               Traceback (most recent call last)",
      "\u001b[1;32m_catboost.pyx\u001b[0m in \u001b[0;36m_catboost._CallbackAfterIteration\u001b[1;34m()\u001b[0m\n",
      "\u001b[1;31mSystemError\u001b[0m: <class 'types.SimpleNamespace'> returned a result with an error set",
      "\nThe above exception was the direct cause of the following exception:\n",
      "\u001b[1;31mSystemError\u001b[0m                               Traceback (most recent call last)",
      "\u001b[1;32m_catboost.pyx\u001b[0m in \u001b[0;36m_catboost._CallbackAfterIteration\u001b[1;34m()\u001b[0m\n",
      "\u001b[1;31mSystemError\u001b[0m: <class 'types.SimpleNamespace'> returned a result with an error set",
      "\nThe above exception was the direct cause of the following exception:\n",
      "\u001b[1;31mSystemError\u001b[0m                               Traceback (most recent call last)",
      "\u001b[1;32m_catboost.pyx\u001b[0m in \u001b[0;36m_catboost._CallbackAfterIteration\u001b[1;34m()\u001b[0m\n",
      "\u001b[1;31mSystemError\u001b[0m: <class 'types.SimpleNamespace'> returned a result with an error set",
      "\nThe above exception was the direct cause of the following exception:\n",
      "\u001b[1;31mSystemError\u001b[0m                               Traceback (most recent call last)",
      "\u001b[1;32m_catboost.pyx\u001b[0m in \u001b[0;36m_catboost._CallbackAfterIteration\u001b[1;34m()\u001b[0m\n",
      "\u001b[1;31mSystemError\u001b[0m: <class 'types.SimpleNamespace'> returned a result with an error set",
      "\nThe above exception was the direct cause of the following exception:\n",
      "\u001b[1;31mSystemError\u001b[0m                               Traceback (most recent call last)",
      "\u001b[1;32m_catboost.pyx\u001b[0m in \u001b[0;36m_catboost._CallbackAfterIteration\u001b[1;34m()\u001b[0m\n",
      "\u001b[1;31mSystemError\u001b[0m: <class 'types.SimpleNamespace'> returned a result with an error set",
      "\nThe above exception was the direct cause of the following exception:\n",
      "\u001b[1;31mSystemError\u001b[0m                               Traceback (most recent call last)",
      "\u001b[1;32m_catboost.pyx\u001b[0m in \u001b[0;36m_catboost._CallbackAfterIteration\u001b[1;34m()\u001b[0m\n",
      "\u001b[1;31mSystemError\u001b[0m: <class 'types.SimpleNamespace'> returned a result with an error set",
      "\nThe above exception was the direct cause of the following exception:\n",
      "\u001b[1;31mSystemError\u001b[0m                               Traceback (most recent call last)",
      "\u001b[1;32m_catboost.pyx\u001b[0m in \u001b[0;36m_catboost._CallbackAfterIteration\u001b[1;34m()\u001b[0m\n",
      "\u001b[1;31mSystemError\u001b[0m: <class 'types.SimpleNamespace'> returned a result with an error set",
      "\nThe above exception was the direct cause of the following exception:\n",
      "\u001b[1;31mSystemError\u001b[0m                               Traceback (most recent call last)",
      "\u001b[1;32m_catboost.pyx\u001b[0m in \u001b[0;36m_catboost._CallbackAfterIteration\u001b[1;34m()\u001b[0m\n",
      "\u001b[1;31mSystemError\u001b[0m: <class 'types.SimpleNamespace'> returned a result with an error set",
      "\nThe above exception was the direct cause of the following exception:\n",
      "\u001b[1;31mSystemError\u001b[0m                               Traceback (most recent call last)",
      "\u001b[1;32m_catboost.pyx\u001b[0m in \u001b[0;36m_catboost._CallbackAfterIteration\u001b[1;34m()\u001b[0m\n",
      "\u001b[1;31mSystemError\u001b[0m: <class 'types.SimpleNamespace'> returned a result with an error set",
      "\nThe above exception was the direct cause of the following exception:\n",
      "\u001b[1;31mSystemError\u001b[0m                               Traceback (most recent call last)",
      "\u001b[1;32m_catboost.pyx\u001b[0m in \u001b[0;36m_catboost._CallbackAfterIteration\u001b[1;34m()\u001b[0m\n",
      "\u001b[1;31mSystemError\u001b[0m: <class 'types.SimpleNamespace'> returned a result with an error set",
      "\nThe above exception was the direct cause of the following exception:\n",
      "\u001b[1;31mSystemError\u001b[0m                               Traceback (most recent call last)",
      "\u001b[1;32m_catboost.pyx\u001b[0m in \u001b[0;36m_catboost._CallbackAfterIteration\u001b[1;34m()\u001b[0m\n",
      "\u001b[1;31mSystemError\u001b[0m: <class 'types.SimpleNamespace'> returned a result with an error set",
      "\nThe above exception was the direct cause of the following exception:\n",
      "\u001b[1;31mSystemError\u001b[0m                               Traceback (most recent call last)",
      "\u001b[1;32m_catboost.pyx\u001b[0m in \u001b[0;36m_catboost._CallbackAfterIteration\u001b[1;34m()\u001b[0m\n",
      "\u001b[1;31mSystemError\u001b[0m: <class 'types.SimpleNamespace'> returned a result with an error set",
      "\nThe above exception was the direct cause of the following exception:\n",
      "\u001b[1;31mSystemError\u001b[0m                               Traceback (most recent call last)",
      "\u001b[1;32m_catboost.pyx\u001b[0m in \u001b[0;36m_catboost._CallbackAfterIteration\u001b[1;34m()\u001b[0m\n",
      "\u001b[1;31mSystemError\u001b[0m: <class 'types.SimpleNamespace'> returned a result with an error set",
      "\nThe above exception was the direct cause of the following exception:\n",
      "\u001b[1;31mSystemError\u001b[0m                               Traceback (most recent call last)",
      "\u001b[1;32m_catboost.pyx\u001b[0m in \u001b[0;36m_catboost._CallbackAfterIteration\u001b[1;34m()\u001b[0m\n",
      "\u001b[1;31mSystemError\u001b[0m: <class 'types.SimpleNamespace'> returned a result with an error set",
      "\nThe above exception was the direct cause of the following exception:\n",
      "\u001b[1;31mSystemError\u001b[0m                               Traceback (most recent call last)",
      "\u001b[1;32m_catboost.pyx\u001b[0m in \u001b[0;36m_catboost._CallbackAfterIteration\u001b[1;34m()\u001b[0m\n",
      "\u001b[1;31mSystemError\u001b[0m: <class 'types.SimpleNamespace'> returned a result with an error set",
      "\nThe above exception was the direct cause of the following exception:\n",
      "\u001b[1;31mSystemError\u001b[0m                               Traceback (most recent call last)",
      "\u001b[1;32m_catboost.pyx\u001b[0m in \u001b[0;36m_catboost._CallbackAfterIteration\u001b[1;34m()\u001b[0m\n",
      "\u001b[1;31mSystemError\u001b[0m: <class 'types.SimpleNamespace'> returned a result with an error set",
      "\nThe above exception was the direct cause of the following exception:\n",
      "\u001b[1;31mSystemError\u001b[0m                               Traceback (most recent call last)",
      "\u001b[1;32m_catboost.pyx\u001b[0m in \u001b[0;36m_catboost._CallbackAfterIteration\u001b[1;34m()\u001b[0m\n",
      "\u001b[1;31mSystemError\u001b[0m: <class 'types.SimpleNamespace'> returned a result with an error set",
      "\nThe above exception was the direct cause of the following exception:\n",
      "\u001b[1;31mSystemError\u001b[0m                               Traceback (most recent call last)",
      "\u001b[1;32m_catboost.pyx\u001b[0m in \u001b[0;36m_catboost._CallbackAfterIteration\u001b[1;34m()\u001b[0m\n",
      "\u001b[1;31mSystemError\u001b[0m: <class 'types.SimpleNamespace'> returned a result with an error set",
      "\nThe above exception was the direct cause of the following exception:\n",
      "\u001b[1;31mSystemError\u001b[0m                               Traceback (most recent call last)",
      "\u001b[1;32m_catboost.pyx\u001b[0m in \u001b[0;36m_catboost._CallbackAfterIteration\u001b[1;34m()\u001b[0m\n",
      "\u001b[1;31mSystemError\u001b[0m: <class 'types.SimpleNamespace'> returned a result with an error set",
      "\nThe above exception was the direct cause of the following exception:\n",
      "\u001b[1;31mSystemError\u001b[0m                               Traceback (most recent call last)",
      "\u001b[1;32m_catboost.pyx\u001b[0m in \u001b[0;36m_catboost._CallbackAfterIteration\u001b[1;34m()\u001b[0m\n",
      "\u001b[1;31mSystemError\u001b[0m: <class 'types.SimpleNamespace'> returned a result with an error set",
      "\nThe above exception was the direct cause of the following exception:\n",
      "\u001b[1;31mSystemError\u001b[0m                               Traceback (most recent call last)",
      "\u001b[1;32m_catboost.pyx\u001b[0m in \u001b[0;36m_catboost._CallbackAfterIteration\u001b[1;34m()\u001b[0m\n",
      "\u001b[1;31mSystemError\u001b[0m: <class 'types.SimpleNamespace'> returned a result with an error set",
      "\nThe above exception was the direct cause of the following exception:\n",
      "\u001b[1;31mSystemError\u001b[0m                               Traceback (most recent call last)",
      "\u001b[1;32m_catboost.pyx\u001b[0m in \u001b[0;36m_catboost._CallbackAfterIteration\u001b[1;34m()\u001b[0m\n",
      "\u001b[1;31mSystemError\u001b[0m: <class 'types.SimpleNamespace'> returned a result with an error set",
      "\nThe above exception was the direct cause of the following exception:\n",
      "\u001b[1;31mSystemError\u001b[0m                               Traceback (most recent call last)",
      "\u001b[1;32m_catboost.pyx\u001b[0m in \u001b[0;36m_catboost._CallbackAfterIteration\u001b[1;34m()\u001b[0m\n",
      "\u001b[1;31mSystemError\u001b[0m: <class 'types.SimpleNamespace'> returned a result with an error set",
      "\nThe above exception was the direct cause of the following exception:\n",
      "\u001b[1;31mSystemError\u001b[0m                               Traceback (most recent call last)",
      "\u001b[1;32m_catboost.pyx\u001b[0m in \u001b[0;36m_catboost._CallbackAfterIteration\u001b[1;34m()\u001b[0m\n",
      "\u001b[1;31mSystemError\u001b[0m: <class 'types.SimpleNamespace'> returned a result with an error set",
      "\nThe above exception was the direct cause of the following exception:\n",
      "\u001b[1;31mSystemError\u001b[0m                               Traceback (most recent call last)",
      "\u001b[1;32m_catboost.pyx\u001b[0m in \u001b[0;36m_catboost._CallbackAfterIteration\u001b[1;34m()\u001b[0m\n",
      "\u001b[1;31mSystemError\u001b[0m: <class 'types.SimpleNamespace'> returned a result with an error set",
      "\nThe above exception was the direct cause of the following exception:\n",
      "\u001b[1;31mSystemError\u001b[0m                               Traceback (most recent call last)",
      "\u001b[1;32m_catboost.pyx\u001b[0m in \u001b[0;36m_catboost._CallbackAfterIteration\u001b[1;34m()\u001b[0m\n",
      "\u001b[1;31mSystemError\u001b[0m: <class 'types.SimpleNamespace'> returned a result with an error set",
      "\nThe above exception was the direct cause of the following exception:\n",
      "\u001b[1;31mSystemError\u001b[0m                               Traceback (most recent call last)",
      "\u001b[1;32m_catboost.pyx\u001b[0m in \u001b[0;36m_catboost._CallbackAfterIteration\u001b[1;34m()\u001b[0m\n",
      "\u001b[1;31mSystemError\u001b[0m: <class 'types.SimpleNamespace'> returned a result with an error set",
      "\nThe above exception was the direct cause of the following exception:\n",
      "\u001b[1;31mSystemError\u001b[0m                               Traceback (most recent call last)",
      "\u001b[1;32m_catboost.pyx\u001b[0m in \u001b[0;36m_catboost._CallbackAfterIteration\u001b[1;34m()\u001b[0m\n",
      "\u001b[1;31mSystemError\u001b[0m: <class 'types.SimpleNamespace'> returned a result with an error set",
      "\nThe above exception was the direct cause of the following exception:\n",
      "\u001b[1;31mSystemError\u001b[0m                               Traceback (most recent call last)",
      "\u001b[1;32m_catboost.pyx\u001b[0m in \u001b[0;36m_catboost._CallbackAfterIteration\u001b[1;34m()\u001b[0m\n",
      "\u001b[1;31mSystemError\u001b[0m: <class 'types.SimpleNamespace'> returned a result with an error set",
      "\nThe above exception was the direct cause of the following exception:\n",
      "\u001b[1;31mSystemError\u001b[0m                               Traceback (most recent call last)",
      "\u001b[1;32m_catboost.pyx\u001b[0m in \u001b[0;36m_catboost._CallbackAfterIteration\u001b[1;34m()\u001b[0m\n",
      "\u001b[1;31mSystemError\u001b[0m: <class 'types.SimpleNamespace'> returned a result with an error set",
      "\nThe above exception was the direct cause of the following exception:\n",
      "\u001b[1;31mSystemError\u001b[0m                               Traceback (most recent call last)",
      "\u001b[1;32m_catboost.pyx\u001b[0m in \u001b[0;36m_catboost._CallbackAfterIteration\u001b[1;34m()\u001b[0m\n",
      "\u001b[1;31mSystemError\u001b[0m: <class 'types.SimpleNamespace'> returned a result with an error set",
      "\nThe above exception was the direct cause of the following exception:\n",
      "\u001b[1;31mSystemError\u001b[0m                               Traceback (most recent call last)",
      "\u001b[1;32m_catboost.pyx\u001b[0m in \u001b[0;36m_catboost._CallbackAfterIteration\u001b[1;34m()\u001b[0m\n",
      "\u001b[1;31mSystemError\u001b[0m: <class 'types.SimpleNamespace'> returned a result with an error set",
      "\nThe above exception was the direct cause of the following exception:\n",
      "\u001b[1;31mSystemError\u001b[0m                               Traceback (most recent call last)",
      "\u001b[1;32m_catboost.pyx\u001b[0m in \u001b[0;36m_catboost._CallbackAfterIteration\u001b[1;34m()\u001b[0m\n",
      "\u001b[1;31mSystemError\u001b[0m: <class 'types.SimpleNamespace'> returned a result with an error set",
      "\nThe above exception was the direct cause of the following exception:\n",
      "\u001b[1;31mSystemError\u001b[0m                               Traceback (most recent call last)",
      "\u001b[1;32m_catboost.pyx\u001b[0m in \u001b[0;36m_catboost._CallbackAfterIteration\u001b[1;34m()\u001b[0m\n",
      "\u001b[1;31mSystemError\u001b[0m: <class 'types.SimpleNamespace'> returned a result with an error set",
      "\nThe above exception was the direct cause of the following exception:\n",
      "\u001b[1;31mSystemError\u001b[0m                               Traceback (most recent call last)",
      "\u001b[1;32m_catboost.pyx\u001b[0m in \u001b[0;36m_catboost._CallbackAfterIteration\u001b[1;34m()\u001b[0m\n",
      "\u001b[1;31mSystemError\u001b[0m: <class 'types.SimpleNamespace'> returned a result with an error set",
      "\nThe above exception was the direct cause of the following exception:\n",
      "\u001b[1;31mSystemError\u001b[0m                               Traceback (most recent call last)",
      "\u001b[1;32m_catboost.pyx\u001b[0m in \u001b[0;36m_catboost._CallbackAfterIteration\u001b[1;34m()\u001b[0m\n",
      "\u001b[1;31mSystemError\u001b[0m: <class 'types.SimpleNamespace'> returned a result with an error set",
      "\nThe above exception was the direct cause of the following exception:\n",
      "\u001b[1;31mSystemError\u001b[0m                               Traceback (most recent call last)",
      "\u001b[1;32m_catboost.pyx\u001b[0m in \u001b[0;36m_catboost._CallbackAfterIteration\u001b[1;34m()\u001b[0m\n",
      "\u001b[1;31mSystemError\u001b[0m: <class 'types.SimpleNamespace'> returned a result with an error set",
      "\nThe above exception was the direct cause of the following exception:\n",
      "\u001b[1;31mSystemError\u001b[0m                               Traceback (most recent call last)",
      "\u001b[1;32m_catboost.pyx\u001b[0m in \u001b[0;36m_catboost._CallbackAfterIteration\u001b[1;34m()\u001b[0m\n",
      "\u001b[1;31mSystemError\u001b[0m: <class 'types.SimpleNamespace'> returned a result with an error set",
      "\nThe above exception was the direct cause of the following exception:\n",
      "\u001b[1;31mSystemError\u001b[0m                               Traceback (most recent call last)",
      "\u001b[1;32m_catboost.pyx\u001b[0m in \u001b[0;36m_catboost._CallbackAfterIteration\u001b[1;34m()\u001b[0m\n",
      "\u001b[1;31mSystemError\u001b[0m: <class 'types.SimpleNamespace'> returned a result with an error set",
      "\nThe above exception was the direct cause of the following exception:\n",
      "\u001b[1;31mSystemError\u001b[0m                               Traceback (most recent call last)",
      "\u001b[1;32m_catboost.pyx\u001b[0m in \u001b[0;36m_catboost._CallbackAfterIteration\u001b[1;34m()\u001b[0m\n",
      "\u001b[1;31mSystemError\u001b[0m: <class 'types.SimpleNamespace'> returned a result with an error set",
      "\nThe above exception was the direct cause of the following exception:\n",
      "\u001b[1;31mSystemError\u001b[0m                               Traceback (most recent call last)",
      "\u001b[1;32m_catboost.pyx\u001b[0m in \u001b[0;36m_catboost._CallbackAfterIteration\u001b[1;34m()\u001b[0m\n",
      "\u001b[1;31mSystemError\u001b[0m: <class 'types.SimpleNamespace'> returned a result with an error set",
      "\nThe above exception was the direct cause of the following exception:\n",
      "\u001b[1;31mSystemError\u001b[0m                               Traceback (most recent call last)",
      "\u001b[1;32m_catboost.pyx\u001b[0m in \u001b[0;36m_catboost._CallbackAfterIteration\u001b[1;34m()\u001b[0m\n",
      "\u001b[1;31mSystemError\u001b[0m: <class 'types.SimpleNamespace'> returned a result with an error set",
      "\nThe above exception was the direct cause of the following exception:\n",
      "\u001b[1;31mSystemError\u001b[0m                               Traceback (most recent call last)",
      "\u001b[1;32m_catboost.pyx\u001b[0m in \u001b[0;36m_catboost._CallbackAfterIteration\u001b[1;34m()\u001b[0m\n",
      "\u001b[1;31mSystemError\u001b[0m: <class 'types.SimpleNamespace'> returned a result with an error set",
      "\nThe above exception was the direct cause of the following exception:\n",
      "\u001b[1;31mSystemError\u001b[0m                               Traceback (most recent call last)",
      "\u001b[1;32m_catboost.pyx\u001b[0m in \u001b[0;36m_catboost._CallbackAfterIteration\u001b[1;34m()\u001b[0m\n",
      "\u001b[1;31mSystemError\u001b[0m: <class 'types.SimpleNamespace'> returned a result with an error set",
      "\nThe above exception was the direct cause of the following exception:\n",
      "\u001b[1;31mSystemError\u001b[0m                               Traceback (most recent call last)",
      "\u001b[1;32m_catboost.pyx\u001b[0m in \u001b[0;36m_catboost._CallbackAfterIteration\u001b[1;34m()\u001b[0m\n",
      "\u001b[1;31mSystemError\u001b[0m: <class 'types.SimpleNamespace'> returned a result with an error set",
      "\nThe above exception was the direct cause of the following exception:\n",
      "\u001b[1;31mSystemError\u001b[0m                               Traceback (most recent call last)",
      "\u001b[1;32m_catboost.pyx\u001b[0m in \u001b[0;36m_catboost._CallbackAfterIteration\u001b[1;34m()\u001b[0m\n",
      "\u001b[1;31mSystemError\u001b[0m: <class 'types.SimpleNamespace'> returned a result with an error set",
      "\nThe above exception was the direct cause of the following exception:\n",
      "\u001b[1;31mSystemError\u001b[0m                               Traceback (most recent call last)",
      "\u001b[1;32m_catboost.pyx\u001b[0m in \u001b[0;36m_catboost._CallbackAfterIteration\u001b[1;34m()\u001b[0m\n",
      "\u001b[1;31mSystemError\u001b[0m: <class 'types.SimpleNamespace'> returned a result with an error set",
      "\nThe above exception was the direct cause of the following exception:\n",
      "\u001b[1;31mSystemError\u001b[0m                               Traceback (most recent call last)",
      "\u001b[1;32m_catboost.pyx\u001b[0m in \u001b[0;36m_catboost._CallbackAfterIteration\u001b[1;34m()\u001b[0m\n",
      "\u001b[1;31mSystemError\u001b[0m: <class 'types.SimpleNamespace'> returned a result with an error set",
      "\nThe above exception was the direct cause of the following exception:\n",
      "\u001b[1;31mSystemError\u001b[0m                               Traceback (most recent call last)",
      "\u001b[1;32m_catboost.pyx\u001b[0m in \u001b[0;36m_catboost._CallbackAfterIteration\u001b[1;34m()\u001b[0m\n",
      "\u001b[1;31mSystemError\u001b[0m: <class 'types.SimpleNamespace'> returned a result with an error set",
      "\nThe above exception was the direct cause of the following exception:\n",
      "\u001b[1;31mSystemError\u001b[0m                               Traceback (most recent call last)",
      "\u001b[1;32m_catboost.pyx\u001b[0m in \u001b[0;36m_catboost._CallbackAfterIteration\u001b[1;34m()\u001b[0m\n",
      "\u001b[1;31mSystemError\u001b[0m: <class 'types.SimpleNamespace'> returned a result with an error set",
      "\nThe above exception was the direct cause of the following exception:\n",
      "\u001b[1;31mSystemError\u001b[0m                               Traceback (most recent call last)",
      "\u001b[1;32m_catboost.pyx\u001b[0m in \u001b[0;36m_catboost._CallbackAfterIteration\u001b[1;34m()\u001b[0m\n",
      "\u001b[1;31mSystemError\u001b[0m: <class 'types.SimpleNamespace'> returned a result with an error set",
      "\nThe above exception was the direct cause of the following exception:\n",
      "\u001b[1;31mSystemError\u001b[0m                               Traceback (most recent call last)",
      "\u001b[1;32m_catboost.pyx\u001b[0m in \u001b[0;36m_catboost._CallbackAfterIteration\u001b[1;34m()\u001b[0m\n",
      "\u001b[1;31mSystemError\u001b[0m: <class 'types.SimpleNamespace'> returned a result with an error set",
      "\nThe above exception was the direct cause of the following exception:\n",
      "\u001b[1;31mSystemError\u001b[0m                               Traceback (most recent call last)",
      "\u001b[1;32m_catboost.pyx\u001b[0m in \u001b[0;36m_catboost._CallbackAfterIteration\u001b[1;34m()\u001b[0m\n",
      "\u001b[1;31mSystemError\u001b[0m: <class 'types.SimpleNamespace'> returned a result with an error set",
      "\nThe above exception was the direct cause of the following exception:\n",
      "\u001b[1;31mSystemError\u001b[0m                               Traceback (most recent call last)",
      "\u001b[1;32m_catboost.pyx\u001b[0m in \u001b[0;36m_catboost._CallbackAfterIteration\u001b[1;34m()\u001b[0m\n",
      "\u001b[1;31mSystemError\u001b[0m: <class 'types.SimpleNamespace'> returned a result with an error set",
      "\nThe above exception was the direct cause of the following exception:\n",
      "\u001b[1;31mSystemError\u001b[0m                               Traceback (most recent call last)",
      "\u001b[1;32m_catboost.pyx\u001b[0m in \u001b[0;36m_catboost._CallbackAfterIteration\u001b[1;34m()\u001b[0m\n",
      "\u001b[1;31mSystemError\u001b[0m: <class 'types.SimpleNamespace'> returned a result with an error set",
      "\nThe above exception was the direct cause of the following exception:\n",
      "\u001b[1;31mSystemError\u001b[0m                               Traceback (most recent call last)",
      "\u001b[1;32m_catboost.pyx\u001b[0m in \u001b[0;36m_catboost._CallbackAfterIteration\u001b[1;34m()\u001b[0m\n",
      "\u001b[1;31mSystemError\u001b[0m: <class 'types.SimpleNamespace'> returned a result with an error set",
      "\nThe above exception was the direct cause of the following exception:\n",
      "\u001b[1;31mSystemError\u001b[0m                               Traceback (most recent call last)",
      "\u001b[1;32m_catboost.pyx\u001b[0m in \u001b[0;36m_catboost._CallbackAfterIteration\u001b[1;34m()\u001b[0m\n",
      "\u001b[1;31mSystemError\u001b[0m: <class 'types.SimpleNamespace'> returned a result with an error set",
      "\nThe above exception was the direct cause of the following exception:\n",
      "\u001b[1;31mSystemError\u001b[0m                               Traceback (most recent call last)",
      "\u001b[1;32m_catboost.pyx\u001b[0m in \u001b[0;36m_catboost._CallbackAfterIteration\u001b[1;34m()\u001b[0m\n",
      "\u001b[1;31mSystemError\u001b[0m: <class 'types.SimpleNamespace'> returned a result with an error set",
      "\nThe above exception was the direct cause of the following exception:\n",
      "\u001b[1;31mSystemError\u001b[0m                               Traceback (most recent call last)",
      "\u001b[1;32m_catboost.pyx\u001b[0m in \u001b[0;36m_catboost._CallbackAfterIteration\u001b[1;34m()\u001b[0m\n",
      "\u001b[1;31mSystemError\u001b[0m: <class 'types.SimpleNamespace'> returned a result with an error set",
      "\nThe above exception was the direct cause of the following exception:\n",
      "\u001b[1;31mSystemError\u001b[0m                               Traceback (most recent call last)",
      "\u001b[1;32m_catboost.pyx\u001b[0m in \u001b[0;36m_catboost._CallbackAfterIteration\u001b[1;34m()\u001b[0m\n",
      "\u001b[1;31mSystemError\u001b[0m: <class 'types.SimpleNamespace'> returned a result with an error set",
      "\nThe above exception was the direct cause of the following exception:\n",
      "\u001b[1;31mSystemError\u001b[0m                               Traceback (most recent call last)",
      "\u001b[1;32m_catboost.pyx\u001b[0m in \u001b[0;36m_catboost._CallbackAfterIteration\u001b[1;34m()\u001b[0m\n",
      "\u001b[1;31mSystemError\u001b[0m: <class 'types.SimpleNamespace'> returned a result with an error set",
      "\nThe above exception was the direct cause of the following exception:\n",
      "\u001b[1;31mSystemError\u001b[0m                               Traceback (most recent call last)",
      "\u001b[1;32m_catboost.pyx\u001b[0m in \u001b[0;36m_catboost._CallbackAfterIteration\u001b[1;34m()\u001b[0m\n",
      "\u001b[1;31mSystemError\u001b[0m: <class 'types.SimpleNamespace'> returned a result with an error set",
      "\nThe above exception was the direct cause of the following exception:\n",
      "\u001b[1;31mSystemError\u001b[0m                               Traceback (most recent call last)",
      "\u001b[1;32m_catboost.pyx\u001b[0m in \u001b[0;36m_catboost._CallbackAfterIteration\u001b[1;34m()\u001b[0m\n",
      "\u001b[1;31mSystemError\u001b[0m: <class 'types.SimpleNamespace'> returned a result with an error set",
      "\nThe above exception was the direct cause of the following exception:\n",
      "\u001b[1;31mSystemError\u001b[0m                               Traceback (most recent call last)",
      "\u001b[1;32m_catboost.pyx\u001b[0m in \u001b[0;36m_catboost._CallbackAfterIteration\u001b[1;34m()\u001b[0m\n",
      "\u001b[1;31mSystemError\u001b[0m: <class 'types.SimpleNamespace'> returned a result with an error set",
      "\nThe above exception was the direct cause of the following exception:\n",
      "\u001b[1;31mSystemError\u001b[0m                               Traceback (most recent call last)",
      "\u001b[1;32m_catboost.pyx\u001b[0m in \u001b[0;36m_catboost._CallbackAfterIteration\u001b[1;34m()\u001b[0m\n",
      "\u001b[1;31mSystemError\u001b[0m: <class 'types.SimpleNamespace'> returned a result with an error set",
      "\nThe above exception was the direct cause of the following exception:\n",
      "\u001b[1;31mSystemError\u001b[0m                               Traceback (most recent call last)",
      "\u001b[1;32m_catboost.pyx\u001b[0m in \u001b[0;36m_catboost._CallbackAfterIteration\u001b[1;34m()\u001b[0m\n",
      "\u001b[1;31mSystemError\u001b[0m: <class 'types.SimpleNamespace'> returned a result with an error set",
      "\nThe above exception was the direct cause of the following exception:\n",
      "\u001b[1;31mSystemError\u001b[0m                               Traceback (most recent call last)",
      "\u001b[1;32m_catboost.pyx\u001b[0m in \u001b[0;36m_catboost._CallbackAfterIteration\u001b[1;34m()\u001b[0m\n",
      "\u001b[1;31mSystemError\u001b[0m: <class 'types.SimpleNamespace'> returned a result with an error set",
      "\nThe above exception was the direct cause of the following exception:\n",
      "\u001b[1;31mSystemError\u001b[0m                               Traceback (most recent call last)",
      "\u001b[1;32m_catboost.pyx\u001b[0m in \u001b[0;36m_catboost._CallbackAfterIteration\u001b[1;34m()\u001b[0m\n",
      "\u001b[1;31mSystemError\u001b[0m: <class 'types.SimpleNamespace'> returned a result with an error set",
      "\nThe above exception was the direct cause of the following exception:\n",
      "\u001b[1;31mSystemError\u001b[0m                               Traceback (most recent call last)",
      "\u001b[1;32m_catboost.pyx\u001b[0m in \u001b[0;36m_catboost._CallbackAfterIteration\u001b[1;34m()\u001b[0m\n",
      "\u001b[1;31mSystemError\u001b[0m: <class 'types.SimpleNamespace'> returned a result with an error set",
      "\nThe above exception was the direct cause of the following exception:\n",
      "\u001b[1;31mSystemError\u001b[0m                               Traceback (most recent call last)",
      "\u001b[1;32m_catboost.pyx\u001b[0m in \u001b[0;36m_catboost._CallbackAfterIteration\u001b[1;34m()\u001b[0m\n",
      "\u001b[1;31mSystemError\u001b[0m: <class 'types.SimpleNamespace'> returned a result with an error set",
      "\nThe above exception was the direct cause of the following exception:\n",
      "\u001b[1;31mSystemError\u001b[0m                               Traceback (most recent call last)",
      "\u001b[1;32m_catboost.pyx\u001b[0m in \u001b[0;36m_catboost._CallbackAfterIteration\u001b[1;34m()\u001b[0m\n",
      "\u001b[1;31mSystemError\u001b[0m: <class 'types.SimpleNamespace'> returned a result with an error set",
      "\nThe above exception was the direct cause of the following exception:\n",
      "\u001b[1;31mSystemError\u001b[0m                               Traceback (most recent call last)",
      "\u001b[1;32m_catboost.pyx\u001b[0m in \u001b[0;36m_catboost._CallbackAfterIteration\u001b[1;34m()\u001b[0m\n",
      "\u001b[1;31mSystemError\u001b[0m: <class 'types.SimpleNamespace'> returned a result with an error set",
      "\nThe above exception was the direct cause of the following exception:\n",
      "\u001b[1;31mSystemError\u001b[0m                               Traceback (most recent call last)",
      "\u001b[1;32m_catboost.pyx\u001b[0m in \u001b[0;36m_catboost._CallbackAfterIteration\u001b[1;34m()\u001b[0m\n",
      "\u001b[1;31mSystemError\u001b[0m: <class 'types.SimpleNamespace'> returned a result with an error set",
      "\nThe above exception was the direct cause of the following exception:\n",
      "\u001b[1;31mSystemError\u001b[0m                               Traceback (most recent call last)",
      "\u001b[1;32m_catboost.pyx\u001b[0m in \u001b[0;36m_catboost._CallbackAfterIteration\u001b[1;34m()\u001b[0m\n",
      "\u001b[1;31mSystemError\u001b[0m: <class 'types.SimpleNamespace'> returned a result with an error set",
      "\nThe above exception was the direct cause of the following exception:\n",
      "\u001b[1;31mSystemError\u001b[0m                               Traceback (most recent call last)",
      "\u001b[1;32m_catboost.pyx\u001b[0m in \u001b[0;36m_catboost._CallbackAfterIteration\u001b[1;34m()\u001b[0m\n",
      "\u001b[1;31mSystemError\u001b[0m: <class 'types.SimpleNamespace'> returned a result with an error set",
      "\nThe above exception was the direct cause of the following exception:\n",
      "\u001b[1;31mSystemError\u001b[0m                               Traceback (most recent call last)",
      "\u001b[1;32m_catboost.pyx\u001b[0m in \u001b[0;36m_catboost._CallbackAfterIteration\u001b[1;34m()\u001b[0m\n",
      "\u001b[1;31mSystemError\u001b[0m: <class 'types.SimpleNamespace'> returned a result with an error set",
      "\nThe above exception was the direct cause of the following exception:\n",
      "\u001b[1;31mSystemError\u001b[0m                               Traceback (most recent call last)",
      "\u001b[1;32m_catboost.pyx\u001b[0m in \u001b[0;36m_catboost._CallbackAfterIteration\u001b[1;34m()\u001b[0m\n",
      "\u001b[1;31mSystemError\u001b[0m: <class 'types.SimpleNamespace'> returned a result with an error set",
      "\nThe above exception was the direct cause of the following exception:\n",
      "\u001b[1;31mSystemError\u001b[0m                               Traceback (most recent call last)",
      "\u001b[1;32m_catboost.pyx\u001b[0m in \u001b[0;36m_catboost._CallbackAfterIteration\u001b[1;34m()\u001b[0m\n",
      "\u001b[1;31mSystemError\u001b[0m: <class 'types.SimpleNamespace'> returned a result with an error set",
      "\nThe above exception was the direct cause of the following exception:\n",
      "\u001b[1;31mSystemError\u001b[0m                               Traceback (most recent call last)",
      "\u001b[1;32m_catboost.pyx\u001b[0m in \u001b[0;36m_catboost._CallbackAfterIteration\u001b[1;34m()\u001b[0m\n",
      "\u001b[1;31mSystemError\u001b[0m: <class 'types.SimpleNamespace'> returned a result with an error set",
      "\nThe above exception was the direct cause of the following exception:\n",
      "\u001b[1;31mSystemError\u001b[0m                               Traceback (most recent call last)",
      "\u001b[1;32m_catboost.pyx\u001b[0m in \u001b[0;36m_catboost._CallbackAfterIteration\u001b[1;34m()\u001b[0m\n",
      "\u001b[1;31mSystemError\u001b[0m: <class 'types.SimpleNamespace'> returned a result with an error set",
      "\nThe above exception was the direct cause of the following exception:\n",
      "\u001b[1;31mSystemError\u001b[0m                               Traceback (most recent call last)",
      "\u001b[1;32m_catboost.pyx\u001b[0m in \u001b[0;36m_catboost._CallbackAfterIteration\u001b[1;34m()\u001b[0m\n",
      "\u001b[1;31mSystemError\u001b[0m: <class 'types.SimpleNamespace'> returned a result with an error set",
      "\nThe above exception was the direct cause of the following exception:\n",
      "\u001b[1;31mSystemError\u001b[0m                               Traceback (most recent call last)",
      "\u001b[1;32m_catboost.pyx\u001b[0m in \u001b[0;36m_catboost._CallbackAfterIteration\u001b[1;34m()\u001b[0m\n",
      "\u001b[1;31mSystemError\u001b[0m: <class 'types.SimpleNamespace'> returned a result with an error set",
      "\nThe above exception was the direct cause of the following exception:\n",
      "\u001b[1;31mSystemError\u001b[0m                               Traceback (most recent call last)",
      "\u001b[1;32m_catboost.pyx\u001b[0m in \u001b[0;36m_catboost._CallbackAfterIteration\u001b[1;34m()\u001b[0m\n",
      "\u001b[1;31mSystemError\u001b[0m: <class 'types.SimpleNamespace'> returned a result with an error set",
      "\nThe above exception was the direct cause of the following exception:\n",
      "\u001b[1;31mSystemError\u001b[0m                               Traceback (most recent call last)",
      "\u001b[1;32m_catboost.pyx\u001b[0m in \u001b[0;36m_catboost._CallbackAfterIteration\u001b[1;34m()\u001b[0m\n",
      "\u001b[1;31mSystemError\u001b[0m: <class 'types.SimpleNamespace'> returned a result with an error set",
      "\nThe above exception was the direct cause of the following exception:\n",
      "\u001b[1;31mSystemError\u001b[0m                               Traceback (most recent call last)",
      "\u001b[1;32m_catboost.pyx\u001b[0m in \u001b[0;36m_catboost._CallbackAfterIteration\u001b[1;34m()\u001b[0m\n",
      "\u001b[1;31mSystemError\u001b[0m: <class 'types.SimpleNamespace'> returned a result with an error set",
      "\nThe above exception was the direct cause of the following exception:\n",
      "\u001b[1;31mSystemError\u001b[0m                               Traceback (most recent call last)",
      "\u001b[1;32m_catboost.pyx\u001b[0m in \u001b[0;36m_catboost._CallbackAfterIteration\u001b[1;34m()\u001b[0m\n",
      "\u001b[1;31mSystemError\u001b[0m: <class 'types.SimpleNamespace'> returned a result with an error set",
      "\nThe above exception was the direct cause of the following exception:\n",
      "\u001b[1;31mSystemError\u001b[0m                               Traceback (most recent call last)",
      "\u001b[1;32m_catboost.pyx\u001b[0m in \u001b[0;36m_catboost._CallbackAfterIteration\u001b[1;34m()\u001b[0m\n",
      "\u001b[1;31mSystemError\u001b[0m: <class 'types.SimpleNamespace'> returned a result with an error set",
      "\nThe above exception was the direct cause of the following exception:\n",
      "\u001b[1;31mSystemError\u001b[0m                               Traceback (most recent call last)",
      "\u001b[1;32m_catboost.pyx\u001b[0m in \u001b[0;36m_catboost._CallbackAfterIteration\u001b[1;34m()\u001b[0m\n",
      "\u001b[1;31mSystemError\u001b[0m: <class 'types.SimpleNamespace'> returned a result with an error set",
      "\nThe above exception was the direct cause of the following exception:\n",
      "\u001b[1;31mSystemError\u001b[0m                               Traceback (most recent call last)",
      "\u001b[1;32m_catboost.pyx\u001b[0m in \u001b[0;36m_catboost._CallbackAfterIteration\u001b[1;34m()\u001b[0m\n",
      "\u001b[1;31mSystemError\u001b[0m: <class 'types.SimpleNamespace'> returned a result with an error set",
      "\nThe above exception was the direct cause of the following exception:\n",
      "\u001b[1;31mSystemError\u001b[0m                               Traceback (most recent call last)",
      "\u001b[1;32m_catboost.pyx\u001b[0m in \u001b[0;36m_catboost._CallbackAfterIteration\u001b[1;34m()\u001b[0m\n",
      "\u001b[1;31mSystemError\u001b[0m: <class 'types.SimpleNamespace'> returned a result with an error set",
      "\nThe above exception was the direct cause of the following exception:\n",
      "\u001b[1;31mSystemError\u001b[0m                               Traceback (most recent call last)",
      "\u001b[1;32m_catboost.pyx\u001b[0m in \u001b[0;36m_catboost._CallbackAfterIteration\u001b[1;34m()\u001b[0m\n",
      "\u001b[1;31mSystemError\u001b[0m: <class 'types.SimpleNamespace'> returned a result with an error set",
      "\nThe above exception was the direct cause of the following exception:\n",
      "\u001b[1;31mSystemError\u001b[0m                               Traceback (most recent call last)",
      "\u001b[1;32m_catboost.pyx\u001b[0m in \u001b[0;36m_catboost._CallbackAfterIteration\u001b[1;34m()\u001b[0m\n",
      "\u001b[1;31mSystemError\u001b[0m: <class 'types.SimpleNamespace'> returned a result with an error set",
      "\nThe above exception was the direct cause of the following exception:\n",
      "\u001b[1;31mSystemError\u001b[0m                               Traceback (most recent call last)",
      "\u001b[1;32m_catboost.pyx\u001b[0m in \u001b[0;36m_catboost._CallbackAfterIteration\u001b[1;34m()\u001b[0m\n",
      "\u001b[1;31mSystemError\u001b[0m: <class 'types.SimpleNamespace'> returned a result with an error set",
      "\nThe above exception was the direct cause of the following exception:\n",
      "\u001b[1;31mSystemError\u001b[0m                               Traceback (most recent call last)",
      "\u001b[1;32m_catboost.pyx\u001b[0m in \u001b[0;36m_catboost._CallbackAfterIteration\u001b[1;34m()\u001b[0m\n",
      "\u001b[1;31mSystemError\u001b[0m: <class 'types.SimpleNamespace'> returned a result with an error set",
      "\nThe above exception was the direct cause of the following exception:\n",
      "\u001b[1;31mSystemError\u001b[0m                               Traceback (most recent call last)",
      "\u001b[1;32m_catboost.pyx\u001b[0m in \u001b[0;36m_catboost._CallbackAfterIteration\u001b[1;34m()\u001b[0m\n",
      "\u001b[1;31mSystemError\u001b[0m: <class 'types.SimpleNamespace'> returned a result with an error set",
      "\nThe above exception was the direct cause of the following exception:\n",
      "\u001b[1;31mSystemError\u001b[0m                               Traceback (most recent call last)",
      "\u001b[1;32m_catboost.pyx\u001b[0m in \u001b[0;36m_catboost._CallbackAfterIteration\u001b[1;34m()\u001b[0m\n",
      "\u001b[1;31mSystemError\u001b[0m: <class 'types.SimpleNamespace'> returned a result with an error set",
      "\nThe above exception was the direct cause of the following exception:\n",
      "\u001b[1;31mSystemError\u001b[0m                               Traceback (most recent call last)",
      "\u001b[1;32m_catboost.pyx\u001b[0m in \u001b[0;36m_catboost._CallbackAfterIteration\u001b[1;34m()\u001b[0m\n",
      "\u001b[1;31mSystemError\u001b[0m: <class 'types.SimpleNamespace'> returned a result with an error set",
      "\nThe above exception was the direct cause of the following exception:\n",
      "\u001b[1;31mSystemError\u001b[0m                               Traceback (most recent call last)",
      "\u001b[1;32m_catboost.pyx\u001b[0m in \u001b[0;36m_catboost._CallbackAfterIteration\u001b[1;34m()\u001b[0m\n",
      "\u001b[1;31mSystemError\u001b[0m: <class 'types.SimpleNamespace'> returned a result with an error set",
      "\nThe above exception was the direct cause of the following exception:\n",
      "\u001b[1;31mSystemError\u001b[0m                               Traceback (most recent call last)",
      "\u001b[1;32m_catboost.pyx\u001b[0m in \u001b[0;36m_catboost._CallbackAfterIteration\u001b[1;34m()\u001b[0m\n",
      "\u001b[1;31mSystemError\u001b[0m: <class 'types.SimpleNamespace'> returned a result with an error set",
      "\nThe above exception was the direct cause of the following exception:\n",
      "\u001b[1;31mSystemError\u001b[0m                               Traceback (most recent call last)",
      "\u001b[1;32m_catboost.pyx\u001b[0m in \u001b[0;36m_catboost._CallbackAfterIteration\u001b[1;34m()\u001b[0m\n",
      "\u001b[1;31mSystemError\u001b[0m: <class 'types.SimpleNamespace'> returned a result with an error set",
      "\nThe above exception was the direct cause of the following exception:\n",
      "\u001b[1;31mSystemError\u001b[0m                               Traceback (most recent call last)",
      "\u001b[1;32m_catboost.pyx\u001b[0m in \u001b[0;36m_catboost._CallbackAfterIteration\u001b[1;34m()\u001b[0m\n",
      "\u001b[1;31mSystemError\u001b[0m: <class 'types.SimpleNamespace'> returned a result with an error set",
      "\nThe above exception was the direct cause of the following exception:\n",
      "\u001b[1;31mSystemError\u001b[0m                               Traceback (most recent call last)",
      "\u001b[1;32m_catboost.pyx\u001b[0m in \u001b[0;36m_catboost._CallbackAfterIteration\u001b[1;34m()\u001b[0m\n",
      "\u001b[1;31mSystemError\u001b[0m: <class 'types.SimpleNamespace'> returned a result with an error set",
      "\nThe above exception was the direct cause of the following exception:\n",
      "\u001b[1;31mSystemError\u001b[0m                               Traceback (most recent call last)",
      "\u001b[1;32m_catboost.pyx\u001b[0m in \u001b[0;36m_catboost._CallbackAfterIteration\u001b[1;34m()\u001b[0m\n",
      "\u001b[1;31mSystemError\u001b[0m: <class 'types.SimpleNamespace'> returned a result with an error set",
      "\nThe above exception was the direct cause of the following exception:\n",
      "\u001b[1;31mSystemError\u001b[0m                               Traceback (most recent call last)",
      "\u001b[1;32m_catboost.pyx\u001b[0m in \u001b[0;36m_catboost._CallbackAfterIteration\u001b[1;34m()\u001b[0m\n",
      "\u001b[1;31mSystemError\u001b[0m: <class 'types.SimpleNamespace'> returned a result with an error set",
      "\nThe above exception was the direct cause of the following exception:\n",
      "\u001b[1;31mSystemError\u001b[0m                               Traceback (most recent call last)",
      "\u001b[1;32m_catboost.pyx\u001b[0m in \u001b[0;36m_catboost._CallbackAfterIteration\u001b[1;34m()\u001b[0m\n",
      "\u001b[1;31mSystemError\u001b[0m: <class 'types.SimpleNamespace'> returned a result with an error set",
      "\nThe above exception was the direct cause of the following exception:\n",
      "\u001b[1;31mSystemError\u001b[0m                               Traceback (most recent call last)",
      "\u001b[1;32m_catboost.pyx\u001b[0m in \u001b[0;36m_catboost._CallbackAfterIteration\u001b[1;34m()\u001b[0m\n",
      "\u001b[1;31mSystemError\u001b[0m: <class 'types.SimpleNamespace'> returned a result with an error set",
      "\nThe above exception was the direct cause of the following exception:\n",
      "\u001b[1;31mSystemError\u001b[0m                               Traceback (most recent call last)",
      "\u001b[1;32m_catboost.pyx\u001b[0m in \u001b[0;36m_catboost._CallbackAfterIteration\u001b[1;34m()\u001b[0m\n",
      "\u001b[1;31mSystemError\u001b[0m: <class 'types.SimpleNamespace'> returned a result with an error set",
      "\nThe above exception was the direct cause of the following exception:\n",
      "\u001b[1;31mSystemError\u001b[0m                               Traceback (most recent call last)",
      "\u001b[1;32m_catboost.pyx\u001b[0m in \u001b[0;36m_catboost._CallbackAfterIteration\u001b[1;34m()\u001b[0m\n",
      "\u001b[1;31mSystemError\u001b[0m: <class 'types.SimpleNamespace'> returned a result with an error set",
      "\nThe above exception was the direct cause of the following exception:\n",
      "\u001b[1;31mSystemError\u001b[0m                               Traceback (most recent call last)",
      "\u001b[1;32m_catboost.pyx\u001b[0m in \u001b[0;36m_catboost._CallbackAfterIteration\u001b[1;34m()\u001b[0m\n",
      "\u001b[1;31mSystemError\u001b[0m: <class 'types.SimpleNamespace'> returned a result with an error set",
      "\nThe above exception was the direct cause of the following exception:\n",
      "\u001b[1;31mSystemError\u001b[0m                               Traceback (most recent call last)",
      "\u001b[1;32m_catboost.pyx\u001b[0m in \u001b[0;36m_catboost._CallbackAfterIteration\u001b[1;34m()\u001b[0m\n",
      "\u001b[1;31mSystemError\u001b[0m: <class 'types.SimpleNamespace'> returned a result with an error set",
      "\nThe above exception was the direct cause of the following exception:\n",
      "\u001b[1;31mSystemError\u001b[0m                               Traceback (most recent call last)",
      "\u001b[1;32m_catboost.pyx\u001b[0m in \u001b[0;36m_catboost._CallbackAfterIteration\u001b[1;34m()\u001b[0m\n",
      "\u001b[1;31mSystemError\u001b[0m: <class 'types.SimpleNamespace'> returned a result with an error set",
      "\nThe above exception was the direct cause of the following exception:\n",
      "\u001b[1;31mSystemError\u001b[0m                               Traceback (most recent call last)",
      "\u001b[1;32m_catboost.pyx\u001b[0m in \u001b[0;36m_catboost._CallbackAfterIteration\u001b[1;34m()\u001b[0m\n",
      "\u001b[1;31mSystemError\u001b[0m: <class 'types.SimpleNamespace'> returned a result with an error set",
      "\nThe above exception was the direct cause of the following exception:\n",
      "\u001b[1;31mSystemError\u001b[0m                               Traceback (most recent call last)",
      "\u001b[1;32m_catboost.pyx\u001b[0m in \u001b[0;36m_catboost._CallbackAfterIteration\u001b[1;34m()\u001b[0m\n",
      "\u001b[1;31mSystemError\u001b[0m: <class 'types.SimpleNamespace'> returned a result with an error set",
      "\nThe above exception was the direct cause of the following exception:\n",
      "\u001b[1;31mSystemError\u001b[0m                               Traceback (most recent call last)",
      "\u001b[1;32m_catboost.pyx\u001b[0m in \u001b[0;36m_catboost._CallbackAfterIteration\u001b[1;34m()\u001b[0m\n",
      "\u001b[1;31mSystemError\u001b[0m: <class 'types.SimpleNamespace'> returned a result with an error set",
      "\nThe above exception was the direct cause of the following exception:\n",
      "\u001b[1;31mSystemError\u001b[0m                               Traceback (most recent call last)",
      "\u001b[1;32m_catboost.pyx\u001b[0m in \u001b[0;36m_catboost._CallbackAfterIteration\u001b[1;34m()\u001b[0m\n",
      "\u001b[1;31mSystemError\u001b[0m: <class 'types.SimpleNamespace'> returned a result with an error set",
      "\nThe above exception was the direct cause of the following exception:\n",
      "\u001b[1;31mSystemError\u001b[0m                               Traceback (most recent call last)",
      "\u001b[1;32m_catboost.pyx\u001b[0m in \u001b[0;36m_catboost._CallbackAfterIteration\u001b[1;34m()\u001b[0m\n",
      "\u001b[1;31mSystemError\u001b[0m: <class 'types.SimpleNamespace'> returned a result with an error set",
      "\nThe above exception was the direct cause of the following exception:\n",
      "\u001b[1;31mSystemError\u001b[0m                               Traceback (most recent call last)",
      "\u001b[1;32m_catboost.pyx\u001b[0m in \u001b[0;36m_catboost._CallbackAfterIteration\u001b[1;34m()\u001b[0m\n",
      "\u001b[1;31mSystemError\u001b[0m: <class 'types.SimpleNamespace'> returned a result with an error set",
      "\nThe above exception was the direct cause of the following exception:\n",
      "\u001b[1;31mSystemError\u001b[0m                               Traceback (most recent call last)",
      "\u001b[1;32m_catboost.pyx\u001b[0m in \u001b[0;36m_catboost._CallbackAfterIteration\u001b[1;34m()\u001b[0m\n",
      "\u001b[1;31mSystemError\u001b[0m: <class 'types.SimpleNamespace'> returned a result with an error set",
      "\nThe above exception was the direct cause of the following exception:\n",
      "\u001b[1;31mSystemError\u001b[0m                               Traceback (most recent call last)",
      "\u001b[1;32m_catboost.pyx\u001b[0m in \u001b[0;36m_catboost._CallbackAfterIteration\u001b[1;34m()\u001b[0m\n",
      "\u001b[1;31mSystemError\u001b[0m: <class 'types.SimpleNamespace'> returned a result with an error set",
      "\nThe above exception was the direct cause of the following exception:\n",
      "\u001b[1;31mSystemError\u001b[0m                               Traceback (most recent call last)",
      "\u001b[1;32m_catboost.pyx\u001b[0m in \u001b[0;36m_catboost._CallbackAfterIteration\u001b[1;34m()\u001b[0m\n",
      "\u001b[1;31mSystemError\u001b[0m: <class 'types.SimpleNamespace'> returned a result with an error set",
      "\nThe above exception was the direct cause of the following exception:\n",
      "\u001b[1;31mSystemError\u001b[0m                               Traceback (most recent call last)",
      "\u001b[1;32m_catboost.pyx\u001b[0m in \u001b[0;36m_catboost._CallbackAfterIteration\u001b[1;34m()\u001b[0m\n",
      "\u001b[1;31mSystemError\u001b[0m: <class 'types.SimpleNamespace'> returned a result with an error set",
      "\nThe above exception was the direct cause of the following exception:\n",
      "\u001b[1;31mSystemError\u001b[0m                               Traceback (most recent call last)",
      "\u001b[1;32m_catboost.pyx\u001b[0m in \u001b[0;36m_catboost._CallbackAfterIteration\u001b[1;34m()\u001b[0m\n",
      "\u001b[1;31mSystemError\u001b[0m: <class 'types.SimpleNamespace'> returned a result with an error set",
      "\nThe above exception was the direct cause of the following exception:\n",
      "\u001b[1;31mSystemError\u001b[0m                               Traceback (most recent call last)",
      "\u001b[1;32m_catboost.pyx\u001b[0m in \u001b[0;36m_catboost._CallbackAfterIteration\u001b[1;34m()\u001b[0m\n",
      "\u001b[1;31mSystemError\u001b[0m: <class 'types.SimpleNamespace'> returned a result with an error set",
      "\nThe above exception was the direct cause of the following exception:\n",
      "\u001b[1;31mSystemError\u001b[0m                               Traceback (most recent call last)",
      "\u001b[1;32m_catboost.pyx\u001b[0m in \u001b[0;36m_catboost._CallbackAfterIteration\u001b[1;34m()\u001b[0m\n",
      "\u001b[1;31mSystemError\u001b[0m: <class 'types.SimpleNamespace'> returned a result with an error set",
      "\nThe above exception was the direct cause of the following exception:\n",
      "\u001b[1;31mSystemError\u001b[0m                               Traceback (most recent call last)",
      "\u001b[1;32m_catboost.pyx\u001b[0m in \u001b[0;36m_catboost._CallbackAfterIteration\u001b[1;34m()\u001b[0m\n",
      "\u001b[1;31mSystemError\u001b[0m: <class 'types.SimpleNamespace'> returned a result with an error set",
      "\nThe above exception was the direct cause of the following exception:\n",
      "\u001b[1;31mSystemError\u001b[0m                               Traceback (most recent call last)",
      "\u001b[1;32m_catboost.pyx\u001b[0m in \u001b[0;36m_catboost._CallbackAfterIteration\u001b[1;34m()\u001b[0m\n",
      "\u001b[1;31mSystemError\u001b[0m: <class 'types.SimpleNamespace'> returned a result with an error set",
      "\nThe above exception was the direct cause of the following exception:\n",
      "\u001b[1;31mSystemError\u001b[0m                               Traceback (most recent call last)",
      "\u001b[1;32m_catboost.pyx\u001b[0m in \u001b[0;36m_catboost._CallbackAfterIteration\u001b[1;34m()\u001b[0m\n",
      "\u001b[1;31mSystemError\u001b[0m: <class 'types.SimpleNamespace'> returned a result with an error set",
      "\nThe above exception was the direct cause of the following exception:\n",
      "\u001b[1;31mSystemError\u001b[0m                               Traceback (most recent call last)",
      "\u001b[1;32m_catboost.pyx\u001b[0m in \u001b[0;36m_catboost._CallbackAfterIteration\u001b[1;34m()\u001b[0m\n",
      "\u001b[1;31mSystemError\u001b[0m: <class 'types.SimpleNamespace'> returned a result with an error set",
      "\nThe above exception was the direct cause of the following exception:\n",
      "\u001b[1;31mSystemError\u001b[0m                               Traceback (most recent call last)",
      "\u001b[1;32m_catboost.pyx\u001b[0m in \u001b[0;36m_catboost._CallbackAfterIteration\u001b[1;34m()\u001b[0m\n",
      "\u001b[1;31mSystemError\u001b[0m: <class 'types.SimpleNamespace'> returned a result with an error set",
      "\nThe above exception was the direct cause of the following exception:\n",
      "\u001b[1;31mSystemError\u001b[0m                               Traceback (most recent call last)",
      "\u001b[1;32m_catboost.pyx\u001b[0m in \u001b[0;36m_catboost._CallbackAfterIteration\u001b[1;34m()\u001b[0m\n",
      "\u001b[1;31mSystemError\u001b[0m: <class 'types.SimpleNamespace'> returned a result with an error set",
      "\nThe above exception was the direct cause of the following exception:\n",
      "\u001b[1;31mSystemError\u001b[0m                               Traceback (most recent call last)",
      "\u001b[1;32m_catboost.pyx\u001b[0m in \u001b[0;36m_catboost._CallbackAfterIteration\u001b[1;34m()\u001b[0m\n",
      "\u001b[1;31mSystemError\u001b[0m: <class 'types.SimpleNamespace'> returned a result with an error set",
      "\nThe above exception was the direct cause of the following exception:\n",
      "\u001b[1;31mSystemError\u001b[0m                               Traceback (most recent call last)",
      "\u001b[1;32m_catboost.pyx\u001b[0m in \u001b[0;36m_catboost._CallbackAfterIteration\u001b[1;34m()\u001b[0m\n",
      "\u001b[1;31mSystemError\u001b[0m: <class 'types.SimpleNamespace'> returned a result with an error set",
      "\nThe above exception was the direct cause of the following exception:\n",
      "\u001b[1;31mSystemError\u001b[0m                               Traceback (most recent call last)",
      "\u001b[1;32m_catboost.pyx\u001b[0m in \u001b[0;36m_catboost._CallbackAfterIteration\u001b[1;34m()\u001b[0m\n",
      "\u001b[1;31mSystemError\u001b[0m: <class 'types.SimpleNamespace'> returned a result with an error set",
      "\nThe above exception was the direct cause of the following exception:\n",
      "\u001b[1;31mSystemError\u001b[0m                               Traceback (most recent call last)",
      "\u001b[1;32m_catboost.pyx\u001b[0m in \u001b[0;36m_catboost._CallbackAfterIteration\u001b[1;34m()\u001b[0m\n",
      "\u001b[1;31mSystemError\u001b[0m: <class 'types.SimpleNamespace'> returned a result with an error set",
      "\nThe above exception was the direct cause of the following exception:\n",
      "\u001b[1;31mSystemError\u001b[0m                               Traceback (most recent call last)",
      "\u001b[1;32m_catboost.pyx\u001b[0m in \u001b[0;36m_catboost._CallbackAfterIteration\u001b[1;34m()\u001b[0m\n",
      "\u001b[1;31mSystemError\u001b[0m: <class 'types.SimpleNamespace'> returned a result with an error set",
      "\nThe above exception was the direct cause of the following exception:\n",
      "\u001b[1;31mSystemError\u001b[0m                               Traceback (most recent call last)",
      "\u001b[1;32m_catboost.pyx\u001b[0m in \u001b[0;36m_catboost._CallbackAfterIteration\u001b[1;34m()\u001b[0m\n",
      "\u001b[1;31mSystemError\u001b[0m: <class 'types.SimpleNamespace'> returned a result with an error set",
      "\nThe above exception was the direct cause of the following exception:\n",
      "\u001b[1;31mSystemError\u001b[0m                               Traceback (most recent call last)",
      "\u001b[1;32m_catboost.pyx\u001b[0m in \u001b[0;36m_catboost._CallbackAfterIteration\u001b[1;34m()\u001b[0m\n",
      "\u001b[1;31mSystemError\u001b[0m: <class 'types.SimpleNamespace'> returned a result with an error set",
      "\nThe above exception was the direct cause of the following exception:\n",
      "\u001b[1;31mSystemError\u001b[0m                               Traceback (most recent call last)",
      "\u001b[1;32m_catboost.pyx\u001b[0m in \u001b[0;36m_catboost._CallbackAfterIteration\u001b[1;34m()\u001b[0m\n",
      "\u001b[1;31mSystemError\u001b[0m: <class 'types.SimpleNamespace'> returned a result with an error set",
      "\nThe above exception was the direct cause of the following exception:\n",
      "\u001b[1;31mSystemError\u001b[0m                               Traceback (most recent call last)",
      "\u001b[1;32m_catboost.pyx\u001b[0m in \u001b[0;36m_catboost._CallbackAfterIteration\u001b[1;34m()\u001b[0m\n",
      "\u001b[1;31mSystemError\u001b[0m: <class 'types.SimpleNamespace'> returned a result with an error set",
      "\nThe above exception was the direct cause of the following exception:\n",
      "\u001b[1;31mSystemError\u001b[0m                               Traceback (most recent call last)",
      "\u001b[1;32m_catboost.pyx\u001b[0m in \u001b[0;36m_catboost._CallbackAfterIteration\u001b[1;34m()\u001b[0m\n",
      "\u001b[1;31mSystemError\u001b[0m: <class 'types.SimpleNamespace'> returned a result with an error set",
      "\nThe above exception was the direct cause of the following exception:\n",
      "\u001b[1;31mSystemError\u001b[0m                               Traceback (most recent call last)",
      "\u001b[1;32m_catboost.pyx\u001b[0m in \u001b[0;36m_catboost._CallbackAfterIteration\u001b[1;34m()\u001b[0m\n",
      "\u001b[1;31mSystemError\u001b[0m: <class 'types.SimpleNamespace'> returned a result with an error set",
      "\nThe above exception was the direct cause of the following exception:\n",
      "\u001b[1;31mSystemError\u001b[0m                               Traceback (most recent call last)",
      "\u001b[1;32m_catboost.pyx\u001b[0m in \u001b[0;36m_catboost._CallbackAfterIteration\u001b[1;34m()\u001b[0m\n",
      "\u001b[1;31mSystemError\u001b[0m: <class 'types.SimpleNamespace'> returned a result with an error set",
      "\nThe above exception was the direct cause of the following exception:\n",
      "\u001b[1;31mSystemError\u001b[0m                               Traceback (most recent call last)",
      "\u001b[1;32m_catboost.pyx\u001b[0m in \u001b[0;36m_catboost._CallbackAfterIteration\u001b[1;34m()\u001b[0m\n",
      "\u001b[1;31mSystemError\u001b[0m: <class 'types.SimpleNamespace'> returned a result with an error set",
      "\nThe above exception was the direct cause of the following exception:\n",
      "\u001b[1;31mSystemError\u001b[0m                               Traceback (most recent call last)",
      "\u001b[1;32m_catboost.pyx\u001b[0m in \u001b[0;36m_catboost._CallbackAfterIteration\u001b[1;34m()\u001b[0m\n",
      "\u001b[1;31mSystemError\u001b[0m: <class 'types.SimpleNamespace'> returned a result with an error set",
      "\nThe above exception was the direct cause of the following exception:\n",
      "\u001b[1;31mSystemError\u001b[0m                               Traceback (most recent call last)",
      "\u001b[1;32m_catboost.pyx\u001b[0m in \u001b[0;36m_catboost._CallbackAfterIteration\u001b[1;34m()\u001b[0m\n",
      "\u001b[1;31mSystemError\u001b[0m: <class 'types.SimpleNamespace'> returned a result with an error set",
      "\nThe above exception was the direct cause of the following exception:\n",
      "\u001b[1;31mSystemError\u001b[0m                               Traceback (most recent call last)",
      "\u001b[1;32m_catboost.pyx\u001b[0m in \u001b[0;36m_catboost._CallbackAfterIteration\u001b[1;34m()\u001b[0m\n",
      "\u001b[1;31mSystemError\u001b[0m: <class 'types.SimpleNamespace'> returned a result with an error set",
      "\nThe above exception was the direct cause of the following exception:\n",
      "\u001b[1;31mSystemError\u001b[0m                               Traceback (most recent call last)",
      "\u001b[1;32m_catboost.pyx\u001b[0m in \u001b[0;36m_catboost._CallbackAfterIteration\u001b[1;34m()\u001b[0m\n",
      "\u001b[1;31mSystemError\u001b[0m: <class 'types.SimpleNamespace'> returned a result with an error set",
      "\nThe above exception was the direct cause of the following exception:\n",
      "\u001b[1;31mSystemError\u001b[0m                               Traceback (most recent call last)",
      "\u001b[1;32m_catboost.pyx\u001b[0m in \u001b[0;36m_catboost._CallbackAfterIteration\u001b[1;34m()\u001b[0m\n",
      "\u001b[1;31mSystemError\u001b[0m: <class 'types.SimpleNamespace'> returned a result with an error set",
      "\nThe above exception was the direct cause of the following exception:\n",
      "\u001b[1;31mSystemError\u001b[0m                               Traceback (most recent call last)",
      "\u001b[1;32m_catboost.pyx\u001b[0m in \u001b[0;36m_catboost._CallbackAfterIteration\u001b[1;34m()\u001b[0m\n",
      "\u001b[1;31mSystemError\u001b[0m: <class 'types.SimpleNamespace'> returned a result with an error set",
      "\nThe above exception was the direct cause of the following exception:\n",
      "\u001b[1;31mSystemError\u001b[0m                               Traceback (most recent call last)",
      "\u001b[1;32m_catboost.pyx\u001b[0m in \u001b[0;36m_catboost._CallbackAfterIteration\u001b[1;34m()\u001b[0m\n",
      "\u001b[1;31mSystemError\u001b[0m: <class 'types.SimpleNamespace'> returned a result with an error set",
      "\nThe above exception was the direct cause of the following exception:\n",
      "\u001b[1;31mSystemError\u001b[0m                               Traceback (most recent call last)",
      "\u001b[1;32m_catboost.pyx\u001b[0m in \u001b[0;36m_catboost._CallbackAfterIteration\u001b[1;34m()\u001b[0m\n",
      "\u001b[1;31mSystemError\u001b[0m: <class 'types.SimpleNamespace'> returned a result with an error set",
      "\nThe above exception was the direct cause of the following exception:\n",
      "\u001b[1;31mSystemError\u001b[0m                               Traceback (most recent call last)",
      "\u001b[1;32m_catboost.pyx\u001b[0m in \u001b[0;36m_catboost._CallbackAfterIteration\u001b[1;34m()\u001b[0m\n",
      "\u001b[1;31mSystemError\u001b[0m: <class 'types.SimpleNamespace'> returned a result with an error set",
      "\nThe above exception was the direct cause of the following exception:\n",
      "\u001b[1;31mSystemError\u001b[0m                               Traceback (most recent call last)",
      "\u001b[1;32m_catboost.pyx\u001b[0m in \u001b[0;36m_catboost._CallbackAfterIteration\u001b[1;34m()\u001b[0m\n",
      "\u001b[1;31mSystemError\u001b[0m: <class 'types.SimpleNamespace'> returned a result with an error set",
      "\nThe above exception was the direct cause of the following exception:\n",
      "\u001b[1;31mSystemError\u001b[0m                               Traceback (most recent call last)",
      "\u001b[1;32m_catboost.pyx\u001b[0m in \u001b[0;36m_catboost._CallbackAfterIteration\u001b[1;34m()\u001b[0m\n",
      "\u001b[1;31mSystemError\u001b[0m: <class 'types.SimpleNamespace'> returned a result with an error set",
      "\nThe above exception was the direct cause of the following exception:\n",
      "\u001b[1;31mSystemError\u001b[0m                               Traceback (most recent call last)",
      "\u001b[1;32m_catboost.pyx\u001b[0m in \u001b[0;36m_catboost._CallbackAfterIteration\u001b[1;34m()\u001b[0m\n",
      "\u001b[1;31mSystemError\u001b[0m: <class 'types.SimpleNamespace'> returned a result with an error set",
      "\nThe above exception was the direct cause of the following exception:\n",
      "\u001b[1;31mSystemError\u001b[0m                               Traceback (most recent call last)",
      "\u001b[1;32m_catboost.pyx\u001b[0m in \u001b[0;36m_catboost._CallbackAfterIteration\u001b[1;34m()\u001b[0m\n",
      "\u001b[1;31mSystemError\u001b[0m: <class 'types.SimpleNamespace'> returned a result with an error set",
      "\nThe above exception was the direct cause of the following exception:\n",
      "\u001b[1;31mSystemError\u001b[0m                               Traceback (most recent call last)",
      "\u001b[1;32m_catboost.pyx\u001b[0m in \u001b[0;36m_catboost._CallbackAfterIteration\u001b[1;34m()\u001b[0m\n",
      "\u001b[1;31mSystemError\u001b[0m: <class 'types.SimpleNamespace'> returned a result with an error set",
      "\nThe above exception was the direct cause of the following exception:\n",
      "\u001b[1;31mSystemError\u001b[0m                               Traceback (most recent call last)",
      "\u001b[1;32m_catboost.pyx\u001b[0m in \u001b[0;36m_catboost._CallbackAfterIteration\u001b[1;34m()\u001b[0m\n",
      "\u001b[1;31mSystemError\u001b[0m: <class 'types.SimpleNamespace'> returned a result with an error set",
      "\nThe above exception was the direct cause of the following exception:\n",
      "\u001b[1;31mSystemError\u001b[0m                               Traceback (most recent call last)",
      "\u001b[1;32m_catboost.pyx\u001b[0m in \u001b[0;36m_catboost._CallbackAfterIteration\u001b[1;34m()\u001b[0m\n",
      "\u001b[1;31mSystemError\u001b[0m: <class 'types.SimpleNamespace'> returned a result with an error set",
      "\nThe above exception was the direct cause of the following exception:\n",
      "\u001b[1;31mSystemError\u001b[0m                               Traceback (most recent call last)",
      "\u001b[1;32m_catboost.pyx\u001b[0m in \u001b[0;36m_catboost._CallbackAfterIteration\u001b[1;34m()\u001b[0m\n",
      "\u001b[1;31mSystemError\u001b[0m: <class 'types.SimpleNamespace'> returned a result with an error set",
      "\nThe above exception was the direct cause of the following exception:\n",
      "\u001b[1;31mSystemError\u001b[0m                               Traceback (most recent call last)",
      "\u001b[1;32m_catboost.pyx\u001b[0m in \u001b[0;36m_catboost._CallbackAfterIteration\u001b[1;34m()\u001b[0m\n",
      "\u001b[1;31mSystemError\u001b[0m: <class 'types.SimpleNamespace'> returned a result with an error set",
      "\nThe above exception was the direct cause of the following exception:\n",
      "\u001b[1;31mSystemError\u001b[0m                               Traceback (most recent call last)",
      "\u001b[1;32m_catboost.pyx\u001b[0m in \u001b[0;36m_catboost._CallbackAfterIteration\u001b[1;34m()\u001b[0m\n",
      "\u001b[1;31mSystemError\u001b[0m: <class 'types.SimpleNamespace'> returned a result with an error set",
      "\nThe above exception was the direct cause of the following exception:\n",
      "\u001b[1;31mSystemError\u001b[0m                               Traceback (most recent call last)",
      "\u001b[1;32m_catboost.pyx\u001b[0m in \u001b[0;36m_catboost._CallbackAfterIteration\u001b[1;34m()\u001b[0m\n",
      "\u001b[1;31mSystemError\u001b[0m: <class 'types.SimpleNamespace'> returned a result with an error set",
      "\nThe above exception was the direct cause of the following exception:\n",
      "\u001b[1;31mSystemError\u001b[0m                               Traceback (most recent call last)",
      "\u001b[1;32m_catboost.pyx\u001b[0m in \u001b[0;36m_catboost._CallbackAfterIteration\u001b[1;34m()\u001b[0m\n",
      "\u001b[1;31mSystemError\u001b[0m: <class 'types.SimpleNamespace'> returned a result with an error set",
      "\nThe above exception was the direct cause of the following exception:\n",
      "\u001b[1;31mSystemError\u001b[0m                               Traceback (most recent call last)",
      "\u001b[1;32m_catboost.pyx\u001b[0m in \u001b[0;36m_catboost._CallbackAfterIteration\u001b[1;34m()\u001b[0m\n",
      "\u001b[1;31mSystemError\u001b[0m: <class 'types.SimpleNamespace'> returned a result with an error set",
      "\nThe above exception was the direct cause of the following exception:\n",
      "\u001b[1;31mSystemError\u001b[0m                               Traceback (most recent call last)",
      "\u001b[1;32m_catboost.pyx\u001b[0m in \u001b[0;36m_catboost._CallbackAfterIteration\u001b[1;34m()\u001b[0m\n",
      "\u001b[1;31mSystemError\u001b[0m: <class 'types.SimpleNamespace'> returned a result with an error set",
      "\nThe above exception was the direct cause of the following exception:\n",
      "\u001b[1;31mSystemError\u001b[0m                               Traceback (most recent call last)",
      "\u001b[1;32m_catboost.pyx\u001b[0m in \u001b[0;36m_catboost._CallbackAfterIteration\u001b[1;34m()\u001b[0m\n",
      "\u001b[1;31mSystemError\u001b[0m: <class 'types.SimpleNamespace'> returned a result with an error set",
      "\nThe above exception was the direct cause of the following exception:\n",
      "\u001b[1;31mSystemError\u001b[0m                               Traceback (most recent call last)",
      "\u001b[1;32m_catboost.pyx\u001b[0m in \u001b[0;36m_catboost._CallbackAfterIteration\u001b[1;34m()\u001b[0m\n",
      "\u001b[1;31mSystemError\u001b[0m: <class 'types.SimpleNamespace'> returned a result with an error set",
      "\nThe above exception was the direct cause of the following exception:\n",
      "\u001b[1;31mSystemError\u001b[0m                               Traceback (most recent call last)",
      "\u001b[1;32m_catboost.pyx\u001b[0m in \u001b[0;36m_catboost._CallbackAfterIteration\u001b[1;34m()\u001b[0m\n",
      "\u001b[1;31mSystemError\u001b[0m: <class 'types.SimpleNamespace'> returned a result with an error set",
      "\nThe above exception was the direct cause of the following exception:\n",
      "\u001b[1;31mSystemError\u001b[0m                               Traceback (most recent call last)",
      "\u001b[1;32m_catboost.pyx\u001b[0m in \u001b[0;36m_catboost._CallbackAfterIteration\u001b[1;34m()\u001b[0m\n",
      "\u001b[1;31mSystemError\u001b[0m: <class 'types.SimpleNamespace'> returned a result with an error set",
      "\nThe above exception was the direct cause of the following exception:\n",
      "\u001b[1;31mSystemError\u001b[0m                               Traceback (most recent call last)",
      "\u001b[1;32m_catboost.pyx\u001b[0m in \u001b[0;36m_catboost._CallbackAfterIteration\u001b[1;34m()\u001b[0m\n",
      "\u001b[1;31mSystemError\u001b[0m: <class 'types.SimpleNamespace'> returned a result with an error set",
      "\nThe above exception was the direct cause of the following exception:\n",
      "\u001b[1;31mSystemError\u001b[0m                               Traceback (most recent call last)",
      "\u001b[1;32m_catboost.pyx\u001b[0m in \u001b[0;36m_catboost._CallbackAfterIteration\u001b[1;34m()\u001b[0m\n",
      "\u001b[1;31mSystemError\u001b[0m: <class 'types.SimpleNamespace'> returned a result with an error set",
      "\nThe above exception was the direct cause of the following exception:\n",
      "\u001b[1;31mSystemError\u001b[0m                               Traceback (most recent call last)",
      "\u001b[1;32m_catboost.pyx\u001b[0m in \u001b[0;36m_catboost._CallbackAfterIteration\u001b[1;34m()\u001b[0m\n",
      "\u001b[1;31mSystemError\u001b[0m: <class 'types.SimpleNamespace'> returned a result with an error set",
      "\nThe above exception was the direct cause of the following exception:\n",
      "\u001b[1;31mSystemError\u001b[0m                               Traceback (most recent call last)",
      "\u001b[1;32m_catboost.pyx\u001b[0m in \u001b[0;36m_catboost._CallbackAfterIteration\u001b[1;34m()\u001b[0m\n",
      "\u001b[1;31mSystemError\u001b[0m: <class 'types.SimpleNamespace'> returned a result with an error set",
      "\nThe above exception was the direct cause of the following exception:\n",
      "\u001b[1;31mSystemError\u001b[0m                               Traceback (most recent call last)",
      "\u001b[1;32m_catboost.pyx\u001b[0m in \u001b[0;36m_catboost._CallbackAfterIteration\u001b[1;34m()\u001b[0m\n",
      "\u001b[1;31mSystemError\u001b[0m: <class 'types.SimpleNamespace'> returned a result with an error set",
      "\nThe above exception was the direct cause of the following exception:\n",
      "\u001b[1;31mSystemError\u001b[0m                               Traceback (most recent call last)",
      "\u001b[1;32m_catboost.pyx\u001b[0m in \u001b[0;36m_catboost._CallbackAfterIteration\u001b[1;34m()\u001b[0m\n",
      "\u001b[1;31mSystemError\u001b[0m: <class 'types.SimpleNamespace'> returned a result with an error set",
      "\nThe above exception was the direct cause of the following exception:\n",
      "\u001b[1;31mSystemError\u001b[0m                               Traceback (most recent call last)",
      "\u001b[1;32m_catboost.pyx\u001b[0m in \u001b[0;36m_catboost._CallbackAfterIteration\u001b[1;34m()\u001b[0m\n",
      "\u001b[1;31mSystemError\u001b[0m: <class 'types.SimpleNamespace'> returned a result with an error set",
      "\nThe above exception was the direct cause of the following exception:\n",
      "\u001b[1;31mSystemError\u001b[0m                               Traceback (most recent call last)",
      "\u001b[1;32m_catboost.pyx\u001b[0m in \u001b[0;36m_catboost._CallbackAfterIteration\u001b[1;34m()\u001b[0m\n",
      "\u001b[1;31mSystemError\u001b[0m: <class 'types.SimpleNamespace'> returned a result with an error set",
      "\nThe above exception was the direct cause of the following exception:\n",
      "\u001b[1;31mSystemError\u001b[0m                               Traceback (most recent call last)",
      "\u001b[1;32m_catboost.pyx\u001b[0m in \u001b[0;36m_catboost._CallbackAfterIteration\u001b[1;34m()\u001b[0m\n",
      "\u001b[1;31mSystemError\u001b[0m: <class 'types.SimpleNamespace'> returned a result with an error set",
      "\nThe above exception was the direct cause of the following exception:\n",
      "\u001b[1;31mSystemError\u001b[0m                               Traceback (most recent call last)",
      "\u001b[1;32m_catboost.pyx\u001b[0m in \u001b[0;36m_catboost._CallbackAfterIteration\u001b[1;34m()\u001b[0m\n",
      "\u001b[1;31mSystemError\u001b[0m: <class 'types.SimpleNamespace'> returned a result with an error set",
      "\nThe above exception was the direct cause of the following exception:\n",
      "\u001b[1;31mSystemError\u001b[0m                               Traceback (most recent call last)",
      "\u001b[1;32m_catboost.pyx\u001b[0m in \u001b[0;36m_catboost._CallbackAfterIteration\u001b[1;34m()\u001b[0m\n",
      "\u001b[1;31mSystemError\u001b[0m: <class 'types.SimpleNamespace'> returned a result with an error set",
      "\nThe above exception was the direct cause of the following exception:\n",
      "\u001b[1;31mSystemError\u001b[0m                               Traceback (most recent call last)",
      "\u001b[1;32m_catboost.pyx\u001b[0m in \u001b[0;36m_catboost._CallbackAfterIteration\u001b[1;34m()\u001b[0m\n",
      "\u001b[1;31mSystemError\u001b[0m: <class 'types.SimpleNamespace'> returned a result with an error set",
      "\nThe above exception was the direct cause of the following exception:\n",
      "\u001b[1;31mSystemError\u001b[0m                               Traceback (most recent call last)",
      "\u001b[1;32m_catboost.pyx\u001b[0m in \u001b[0;36m_catboost._CallbackAfterIteration\u001b[1;34m()\u001b[0m\n",
      "\u001b[1;31mSystemError\u001b[0m: <class 'types.SimpleNamespace'> returned a result with an error set",
      "\nThe above exception was the direct cause of the following exception:\n",
      "\u001b[1;31mSystemError\u001b[0m                               Traceback (most recent call last)",
      "\u001b[1;32m_catboost.pyx\u001b[0m in \u001b[0;36m_catboost._CallbackAfterIteration\u001b[1;34m()\u001b[0m\n",
      "\u001b[1;31mSystemError\u001b[0m: <class 'types.SimpleNamespace'> returned a result with an error set",
      "\nThe above exception was the direct cause of the following exception:\n",
      "\u001b[1;31mSystemError\u001b[0m                               Traceback (most recent call last)",
      "\u001b[1;32m_catboost.pyx\u001b[0m in \u001b[0;36m_catboost._CallbackAfterIteration\u001b[1;34m()\u001b[0m\n",
      "\u001b[1;31mSystemError\u001b[0m: <class 'types.SimpleNamespace'> returned a result with an error set",
      "\nThe above exception was the direct cause of the following exception:\n",
      "\u001b[1;31mSystemError\u001b[0m                               Traceback (most recent call last)",
      "\u001b[1;32m_catboost.pyx\u001b[0m in \u001b[0;36m_catboost._CallbackAfterIteration\u001b[1;34m()\u001b[0m\n",
      "\u001b[1;31mSystemError\u001b[0m: <class 'types.SimpleNamespace'> returned a result with an error set",
      "\nThe above exception was the direct cause of the following exception:\n",
      "\u001b[1;31mSystemError\u001b[0m                               Traceback (most recent call last)",
      "\u001b[1;32m_catboost.pyx\u001b[0m in \u001b[0;36m_catboost._CallbackAfterIteration\u001b[1;34m()\u001b[0m\n",
      "\u001b[1;31mSystemError\u001b[0m: <class 'types.SimpleNamespace'> returned a result with an error set",
      "\nThe above exception was the direct cause of the following exception:\n",
      "\u001b[1;31mSystemError\u001b[0m                               Traceback (most recent call last)",
      "\u001b[1;32m_catboost.pyx\u001b[0m in \u001b[0;36m_catboost._CallbackAfterIteration\u001b[1;34m()\u001b[0m\n",
      "\u001b[1;31mSystemError\u001b[0m: <class 'types.SimpleNamespace'> returned a result with an error set",
      "\nThe above exception was the direct cause of the following exception:\n",
      "\u001b[1;31mSystemError\u001b[0m                               Traceback (most recent call last)",
      "\u001b[1;32m_catboost.pyx\u001b[0m in \u001b[0;36m_catboost._CallbackAfterIteration\u001b[1;34m()\u001b[0m\n",
      "\u001b[1;31mSystemError\u001b[0m: <class 'types.SimpleNamespace'> returned a result with an error set",
      "\nThe above exception was the direct cause of the following exception:\n",
      "\u001b[1;31mSystemError\u001b[0m                               Traceback (most recent call last)",
      "\u001b[1;32m_catboost.pyx\u001b[0m in \u001b[0;36m_catboost._CallbackAfterIteration\u001b[1;34m()\u001b[0m\n",
      "\u001b[1;31mSystemError\u001b[0m: <class 'types.SimpleNamespace'> returned a result with an error set",
      "\nThe above exception was the direct cause of the following exception:\n",
      "\u001b[1;31mSystemError\u001b[0m                               Traceback (most recent call last)",
      "\u001b[1;32m_catboost.pyx\u001b[0m in \u001b[0;36m_catboost._CallbackAfterIteration\u001b[1;34m()\u001b[0m\n",
      "\u001b[1;31mSystemError\u001b[0m: <class 'types.SimpleNamespace'> returned a result with an error set",
      "\nThe above exception was the direct cause of the following exception:\n",
      "\u001b[1;31mSystemError\u001b[0m                               Traceback (most recent call last)",
      "\u001b[1;32m_catboost.pyx\u001b[0m in \u001b[0;36m_catboost._CallbackAfterIteration\u001b[1;34m()\u001b[0m\n",
      "\u001b[1;31mSystemError\u001b[0m: <class 'types.SimpleNamespace'> returned a result with an error set",
      "\nThe above exception was the direct cause of the following exception:\n",
      "\u001b[1;31mSystemError\u001b[0m                               Traceback (most recent call last)",
      "\u001b[1;32m_catboost.pyx\u001b[0m in \u001b[0;36m_catboost._CallbackAfterIteration\u001b[1;34m()\u001b[0m\n",
      "\u001b[1;31mSystemError\u001b[0m: <class 'types.SimpleNamespace'> returned a result with an error set",
      "\nThe above exception was the direct cause of the following exception:\n",
      "\u001b[1;31mSystemError\u001b[0m                               Traceback (most recent call last)",
      "\u001b[1;32m_catboost.pyx\u001b[0m in \u001b[0;36m_catboost._CallbackAfterIteration\u001b[1;34m()\u001b[0m\n",
      "\u001b[1;31mSystemError\u001b[0m: <class 'types.SimpleNamespace'> returned a result with an error set",
      "\nThe above exception was the direct cause of the following exception:\n",
      "\u001b[1;31mSystemError\u001b[0m                               Traceback (most recent call last)",
      "\u001b[1;32m_catboost.pyx\u001b[0m in \u001b[0;36m_catboost._CallbackAfterIteration\u001b[1;34m()\u001b[0m\n",
      "\u001b[1;31mSystemError\u001b[0m: <class 'types.SimpleNamespace'> returned a result with an error set",
      "\nThe above exception was the direct cause of the following exception:\n",
      "\u001b[1;31mSystemError\u001b[0m                               Traceback (most recent call last)",
      "\u001b[1;32m_catboost.pyx\u001b[0m in \u001b[0;36m_catboost._CallbackAfterIteration\u001b[1;34m()\u001b[0m\n",
      "\u001b[1;31mSystemError\u001b[0m: <class 'types.SimpleNamespace'> returned a result with an error set",
      "\nThe above exception was the direct cause of the following exception:\n",
      "\u001b[1;31mSystemError\u001b[0m                               Traceback (most recent call last)",
      "\u001b[1;32m_catboost.pyx\u001b[0m in \u001b[0;36m_catboost._CallbackAfterIteration\u001b[1;34m()\u001b[0m\n",
      "\u001b[1;31mSystemError\u001b[0m: <class 'types.SimpleNamespace'> returned a result with an error set",
      "\nThe above exception was the direct cause of the following exception:\n",
      "\u001b[1;31mSystemError\u001b[0m                               Traceback (most recent call last)",
      "\u001b[1;32m_catboost.pyx\u001b[0m in \u001b[0;36m_catboost._CallbackAfterIteration\u001b[1;34m()\u001b[0m\n",
      "\u001b[1;31mSystemError\u001b[0m: <class 'types.SimpleNamespace'> returned a result with an error set",
      "\nThe above exception was the direct cause of the following exception:\n",
      "\u001b[1;31mSystemError\u001b[0m                               Traceback (most recent call last)",
      "\u001b[1;32m_catboost.pyx\u001b[0m in \u001b[0;36m_catboost._CallbackAfterIteration\u001b[1;34m()\u001b[0m\n",
      "\u001b[1;31mSystemError\u001b[0m: <class 'types.SimpleNamespace'> returned a result with an error set",
      "\nThe above exception was the direct cause of the following exception:\n",
      "\u001b[1;31mSystemError\u001b[0m                               Traceback (most recent call last)",
      "\u001b[1;32m_catboost.pyx\u001b[0m in \u001b[0;36m_catboost._CallbackAfterIteration\u001b[1;34m()\u001b[0m\n",
      "\u001b[1;31mSystemError\u001b[0m: <class 'types.SimpleNamespace'> returned a result with an error set",
      "\nThe above exception was the direct cause of the following exception:\n",
      "\u001b[1;31mSystemError\u001b[0m                               Traceback (most recent call last)",
      "\u001b[1;32m_catboost.pyx\u001b[0m in \u001b[0;36m_catboost._CallbackAfterIteration\u001b[1;34m()\u001b[0m\n",
      "\u001b[1;31mSystemError\u001b[0m: <class 'types.SimpleNamespace'> returned a result with an error set",
      "\nThe above exception was the direct cause of the following exception:\n",
      "\u001b[1;31mSystemError\u001b[0m                               Traceback (most recent call last)",
      "\u001b[1;32m_catboost.pyx\u001b[0m in \u001b[0;36m_catboost._CallbackAfterIteration\u001b[1;34m()\u001b[0m\n",
      "\u001b[1;31mSystemError\u001b[0m: <class 'types.SimpleNamespace'> returned a result with an error set",
      "\nThe above exception was the direct cause of the following exception:\n",
      "\u001b[1;31mSystemError\u001b[0m                               Traceback (most recent call last)",
      "\u001b[1;32m_catboost.pyx\u001b[0m in \u001b[0;36m_catboost._CallbackAfterIteration\u001b[1;34m()\u001b[0m\n",
      "\u001b[1;31mSystemError\u001b[0m: <class 'types.SimpleNamespace'> returned a result with an error set",
      "\nThe above exception was the direct cause of the following exception:\n",
      "\u001b[1;31mSystemError\u001b[0m                               Traceback (most recent call last)",
      "\u001b[1;32m_catboost.pyx\u001b[0m in \u001b[0;36m_catboost._CallbackAfterIteration\u001b[1;34m()\u001b[0m\n",
      "\u001b[1;31mSystemError\u001b[0m: <class 'types.SimpleNamespace'> returned a result with an error set",
      "\nThe above exception was the direct cause of the following exception:\n",
      "\u001b[1;31mSystemError\u001b[0m                               Traceback (most recent call last)",
      "\u001b[1;32m_catboost.pyx\u001b[0m in \u001b[0;36m_catboost._CallbackAfterIteration\u001b[1;34m()\u001b[0m\n",
      "\u001b[1;31mSystemError\u001b[0m: <class 'types.SimpleNamespace'> returned a result with an error set",
      "\nThe above exception was the direct cause of the following exception:\n",
      "\u001b[1;31mSystemError\u001b[0m                               Traceback (most recent call last)",
      "\u001b[1;32m_catboost.pyx\u001b[0m in \u001b[0;36m_catboost._CallbackAfterIteration\u001b[1;34m()\u001b[0m\n",
      "\u001b[1;31mSystemError\u001b[0m: <class 'types.SimpleNamespace'> returned a result with an error set",
      "\nThe above exception was the direct cause of the following exception:\n",
      "\u001b[1;31mSystemError\u001b[0m                               Traceback (most recent call last)",
      "\u001b[1;32m_catboost.pyx\u001b[0m in \u001b[0;36m_catboost._CallbackAfterIteration\u001b[1;34m()\u001b[0m\n",
      "\u001b[1;31mSystemError\u001b[0m: <class 'types.SimpleNamespace'> returned a result with an error set",
      "\nThe above exception was the direct cause of the following exception:\n",
      "\u001b[1;31mSystemError\u001b[0m                               Traceback (most recent call last)",
      "\u001b[1;32m_catboost.pyx\u001b[0m in \u001b[0;36m_catboost._CallbackAfterIteration\u001b[1;34m()\u001b[0m\n",
      "\u001b[1;31mSystemError\u001b[0m: <class 'types.SimpleNamespace'> returned a result with an error set",
      "\nThe above exception was the direct cause of the following exception:\n",
      "\u001b[1;31mSystemError\u001b[0m                               Traceback (most recent call last)",
      "\u001b[1;32m_catboost.pyx\u001b[0m in \u001b[0;36m_catboost._CallbackAfterIteration\u001b[1;34m()\u001b[0m\n",
      "\u001b[1;31mSystemError\u001b[0m: <class 'types.SimpleNamespace'> returned a result with an error set",
      "\nThe above exception was the direct cause of the following exception:\n",
      "\u001b[1;31mSystemError\u001b[0m                               Traceback (most recent call last)",
      "\u001b[1;32m_catboost.pyx\u001b[0m in \u001b[0;36m_catboost._CallbackAfterIteration\u001b[1;34m()\u001b[0m\n",
      "\u001b[1;31mSystemError\u001b[0m: <class 'types.SimpleNamespace'> returned a result with an error set",
      "\nThe above exception was the direct cause of the following exception:\n",
      "\u001b[1;31mSystemError\u001b[0m                               Traceback (most recent call last)",
      "\u001b[1;32m_catboost.pyx\u001b[0m in \u001b[0;36m_catboost._CallbackAfterIteration\u001b[1;34m()\u001b[0m\n",
      "\u001b[1;31mSystemError\u001b[0m: <class 'types.SimpleNamespace'> returned a result with an error set",
      "\nThe above exception was the direct cause of the following exception:\n",
      "\u001b[1;31mSystemError\u001b[0m                               Traceback (most recent call last)",
      "\u001b[1;32m_catboost.pyx\u001b[0m in \u001b[0;36m_catboost._CallbackAfterIteration\u001b[1;34m()\u001b[0m\n",
      "\u001b[1;31mSystemError\u001b[0m: <class 'types.SimpleNamespace'> returned a result with an error set",
      "\nThe above exception was the direct cause of the following exception:\n",
      "\u001b[1;31mSystemError\u001b[0m                               Traceback (most recent call last)",
      "\u001b[1;32m_catboost.pyx\u001b[0m in \u001b[0;36m_catboost._CallbackAfterIteration\u001b[1;34m()\u001b[0m\n",
      "\u001b[1;31mSystemError\u001b[0m: <class 'types.SimpleNamespace'> returned a result with an error set",
      "\nThe above exception was the direct cause of the following exception:\n",
      "\u001b[1;31mSystemError\u001b[0m                               Traceback (most recent call last)",
      "\u001b[1;32m_catboost.pyx\u001b[0m in \u001b[0;36m_catboost._CallbackAfterIteration\u001b[1;34m()\u001b[0m\n",
      "\u001b[1;31mSystemError\u001b[0m: <class 'types.SimpleNamespace'> returned a result with an error set",
      "\nThe above exception was the direct cause of the following exception:\n",
      "\u001b[1;31mSystemError\u001b[0m                               Traceback (most recent call last)",
      "\u001b[1;32m_catboost.pyx\u001b[0m in \u001b[0;36m_catboost._CallbackAfterIteration\u001b[1;34m()\u001b[0m\n",
      "\u001b[1;31mSystemError\u001b[0m: <class 'types.SimpleNamespace'> returned a result with an error set",
      "\nThe above exception was the direct cause of the following exception:\n",
      "\u001b[1;31mSystemError\u001b[0m                               Traceback (most recent call last)",
      "\u001b[1;32m_catboost.pyx\u001b[0m in \u001b[0;36m_catboost._CallbackAfterIteration\u001b[1;34m()\u001b[0m\n",
      "\u001b[1;31mSystemError\u001b[0m: <class 'types.SimpleNamespace'> returned a result with an error set",
      "\nThe above exception was the direct cause of the following exception:\n",
      "\u001b[1;31mSystemError\u001b[0m                               Traceback (most recent call last)",
      "\u001b[1;32m_catboost.pyx\u001b[0m in \u001b[0;36m_catboost._CallbackAfterIteration\u001b[1;34m()\u001b[0m\n",
      "\u001b[1;31mSystemError\u001b[0m: <class 'types.SimpleNamespace'> returned a result with an error set",
      "\nThe above exception was the direct cause of the following exception:\n",
      "\u001b[1;31mSystemError\u001b[0m                               Traceback (most recent call last)",
      "\u001b[1;32m_catboost.pyx\u001b[0m in \u001b[0;36m_catboost._CallbackAfterIteration\u001b[1;34m()\u001b[0m\n",
      "\u001b[1;31mSystemError\u001b[0m: <class 'types.SimpleNamespace'> returned a result with an error set",
      "\nThe above exception was the direct cause of the following exception:\n",
      "\u001b[1;31mSystemError\u001b[0m                               Traceback (most recent call last)",
      "\u001b[1;32m_catboost.pyx\u001b[0m in \u001b[0;36m_catboost._CallbackAfterIteration\u001b[1;34m()\u001b[0m\n",
      "\u001b[1;31mSystemError\u001b[0m: <class 'types.SimpleNamespace'> returned a result with an error set",
      "\nThe above exception was the direct cause of the following exception:\n",
      "\u001b[1;31mSystemError\u001b[0m                               Traceback (most recent call last)",
      "\u001b[1;32m_catboost.pyx\u001b[0m in \u001b[0;36m_catboost._CallbackAfterIteration\u001b[1;34m()\u001b[0m\n",
      "\u001b[1;31mSystemError\u001b[0m: <class 'types.SimpleNamespace'> returned a result with an error set",
      "\nThe above exception was the direct cause of the following exception:\n",
      "\u001b[1;31mSystemError\u001b[0m                               Traceback (most recent call last)",
      "\u001b[1;32m_catboost.pyx\u001b[0m in \u001b[0;36m_catboost._CallbackAfterIteration\u001b[1;34m()\u001b[0m\n",
      "\u001b[1;31mSystemError\u001b[0m: <class 'types.SimpleNamespace'> returned a result with an error set",
      "\nThe above exception was the direct cause of the following exception:\n",
      "\u001b[1;31mSystemError\u001b[0m                               Traceback (most recent call last)",
      "\u001b[1;32m_catboost.pyx\u001b[0m in \u001b[0;36m_catboost._CallbackAfterIteration\u001b[1;34m()\u001b[0m\n",
      "\u001b[1;31mSystemError\u001b[0m: <class 'types.SimpleNamespace'> returned a result with an error set",
      "\nThe above exception was the direct cause of the following exception:\n",
      "\u001b[1;31mSystemError\u001b[0m                               Traceback (most recent call last)",
      "\u001b[1;32m_catboost.pyx\u001b[0m in \u001b[0;36m_catboost._CallbackAfterIteration\u001b[1;34m()\u001b[0m\n",
      "\u001b[1;31mSystemError\u001b[0m: <class 'types.SimpleNamespace'> returned a result with an error set",
      "\nThe above exception was the direct cause of the following exception:\n",
      "\u001b[1;31mSystemError\u001b[0m                               Traceback (most recent call last)",
      "\u001b[1;32m_catboost.pyx\u001b[0m in \u001b[0;36m_catboost._CallbackAfterIteration\u001b[1;34m()\u001b[0m\n",
      "\u001b[1;31mSystemError\u001b[0m: <class 'types.SimpleNamespace'> returned a result with an error set",
      "\nThe above exception was the direct cause of the following exception:\n",
      "\u001b[1;31mSystemError\u001b[0m                               Traceback (most recent call last)",
      "\u001b[1;32m_catboost.pyx\u001b[0m in \u001b[0;36m_catboost._CallbackAfterIteration\u001b[1;34m()\u001b[0m\n",
      "\u001b[1;31mSystemError\u001b[0m: <class 'types.SimpleNamespace'> returned a result with an error set",
      "\nThe above exception was the direct cause of the following exception:\n",
      "\u001b[1;31mSystemError\u001b[0m                               Traceback (most recent call last)",
      "\u001b[1;32m_catboost.pyx\u001b[0m in \u001b[0;36m_catboost._CallbackAfterIteration\u001b[1;34m()\u001b[0m\n",
      "\u001b[1;31mSystemError\u001b[0m: <class 'types.SimpleNamespace'> returned a result with an error set",
      "\nThe above exception was the direct cause of the following exception:\n",
      "\u001b[1;31mSystemError\u001b[0m                               Traceback (most recent call last)",
      "\u001b[1;32m_catboost.pyx\u001b[0m in \u001b[0;36m_catboost._CallbackAfterIteration\u001b[1;34m()\u001b[0m\n",
      "\u001b[1;31mSystemError\u001b[0m: <class 'types.SimpleNamespace'> returned a result with an error set",
      "\nThe above exception was the direct cause of the following exception:\n",
      "\u001b[1;31mSystemError\u001b[0m                               Traceback (most recent call last)",
      "\u001b[1;32m_catboost.pyx\u001b[0m in \u001b[0;36m_catboost._CallbackAfterIteration\u001b[1;34m()\u001b[0m\n",
      "\u001b[1;31mSystemError\u001b[0m: <class 'types.SimpleNamespace'> returned a result with an error set",
      "\nThe above exception was the direct cause of the following exception:\n",
      "\u001b[1;31mSystemError\u001b[0m                               Traceback (most recent call last)",
      "\u001b[1;32m_catboost.pyx\u001b[0m in \u001b[0;36m_catboost._CallbackAfterIteration\u001b[1;34m()\u001b[0m\n",
      "\u001b[1;31mSystemError\u001b[0m: <class 'types.SimpleNamespace'> returned a result with an error set",
      "\nThe above exception was the direct cause of the following exception:\n",
      "\u001b[1;31mSystemError\u001b[0m                               Traceback (most recent call last)",
      "\u001b[1;32m_catboost.pyx\u001b[0m in \u001b[0;36m_catboost._CallbackAfterIteration\u001b[1;34m()\u001b[0m\n",
      "\u001b[1;31mSystemError\u001b[0m: <class 'types.SimpleNamespace'> returned a result with an error set",
      "\nThe above exception was the direct cause of the following exception:\n",
      "\u001b[1;31mSystemError\u001b[0m                               Traceback (most recent call last)",
      "\u001b[1;32m_catboost.pyx\u001b[0m in \u001b[0;36m_catboost._CallbackAfterIteration\u001b[1;34m()\u001b[0m\n",
      "\u001b[1;31mSystemError\u001b[0m: <class 'types.SimpleNamespace'> returned a result with an error set",
      "\nThe above exception was the direct cause of the following exception:\n",
      "\u001b[1;31mSystemError\u001b[0m                               Traceback (most recent call last)",
      "\u001b[1;32m_catboost.pyx\u001b[0m in \u001b[0;36m_catboost._CallbackAfterIteration\u001b[1;34m()\u001b[0m\n",
      "\u001b[1;31mSystemError\u001b[0m: <class 'types.SimpleNamespace'> returned a result with an error set",
      "\nThe above exception was the direct cause of the following exception:\n",
      "\u001b[1;31mSystemError\u001b[0m                               Traceback (most recent call last)",
      "\u001b[1;32m_catboost.pyx\u001b[0m in \u001b[0;36m_catboost._CallbackAfterIteration\u001b[1;34m()\u001b[0m\n",
      "\u001b[1;31mSystemError\u001b[0m: <class 'types.SimpleNamespace'> returned a result with an error set",
      "\nThe above exception was the direct cause of the following exception:\n",
      "\u001b[1;31mSystemError\u001b[0m                               Traceback (most recent call last)",
      "\u001b[1;32m_catboost.pyx\u001b[0m in \u001b[0;36m_catboost._CallbackAfterIteration\u001b[1;34m()\u001b[0m\n",
      "\u001b[1;31mSystemError\u001b[0m: <class 'types.SimpleNamespace'> returned a result with an error set",
      "\nThe above exception was the direct cause of the following exception:\n",
      "\u001b[1;31mSystemError\u001b[0m                               Traceback (most recent call last)",
      "\u001b[1;32m_catboost.pyx\u001b[0m in \u001b[0;36m_catboost._CallbackAfterIteration\u001b[1;34m()\u001b[0m\n",
      "\u001b[1;31mSystemError\u001b[0m: <class 'types.SimpleNamespace'> returned a result with an error set",
      "\nThe above exception was the direct cause of the following exception:\n",
      "\u001b[1;31mSystemError\u001b[0m                               Traceback (most recent call last)",
      "\u001b[1;32m_catboost.pyx\u001b[0m in \u001b[0;36m_catboost._CallbackAfterIteration\u001b[1;34m()\u001b[0m\n",
      "\u001b[1;31mSystemError\u001b[0m: <class 'types.SimpleNamespace'> returned a result with an error set",
      "\nThe above exception was the direct cause of the following exception:\n",
      "\u001b[1;31mSystemError\u001b[0m                               Traceback (most recent call last)",
      "\u001b[1;32m_catboost.pyx\u001b[0m in \u001b[0;36m_catboost._CallbackAfterIteration\u001b[1;34m()\u001b[0m\n",
      "\u001b[1;31mSystemError\u001b[0m: <class 'types.SimpleNamespace'> returned a result with an error set",
      "\nThe above exception was the direct cause of the following exception:\n",
      "\u001b[1;31mSystemError\u001b[0m                               Traceback (most recent call last)",
      "\u001b[1;32m_catboost.pyx\u001b[0m in \u001b[0;36m_catboost._CallbackAfterIteration\u001b[1;34m()\u001b[0m\n",
      "\u001b[1;31mSystemError\u001b[0m: <class 'types.SimpleNamespace'> returned a result with an error set",
      "\nThe above exception was the direct cause of the following exception:\n",
      "\u001b[1;31mSystemError\u001b[0m                               Traceback (most recent call last)",
      "\u001b[1;32m_catboost.pyx\u001b[0m in \u001b[0;36m_catboost._CallbackAfterIteration\u001b[1;34m()\u001b[0m\n",
      "\u001b[1;31mSystemError\u001b[0m: <class 'types.SimpleNamespace'> returned a result with an error set",
      "\nThe above exception was the direct cause of the following exception:\n",
      "\u001b[1;31mSystemError\u001b[0m                               Traceback (most recent call last)",
      "\u001b[1;32m_catboost.pyx\u001b[0m in \u001b[0;36m_catboost._CallbackAfterIteration\u001b[1;34m()\u001b[0m\n",
      "\u001b[1;31mSystemError\u001b[0m: <class 'types.SimpleNamespace'> returned a result with an error set",
      "\nThe above exception was the direct cause of the following exception:\n",
      "\u001b[1;31mSystemError\u001b[0m                               Traceback (most recent call last)",
      "\u001b[1;32m_catboost.pyx\u001b[0m in \u001b[0;36m_catboost._CallbackAfterIteration\u001b[1;34m()\u001b[0m\n",
      "\u001b[1;31mSystemError\u001b[0m: <class 'types.SimpleNamespace'> returned a result with an error set",
      "\nThe above exception was the direct cause of the following exception:\n",
      "\u001b[1;31mSystemError\u001b[0m                               Traceback (most recent call last)",
      "\u001b[1;32m_catboost.pyx\u001b[0m in \u001b[0;36m_catboost._CallbackAfterIteration\u001b[1;34m()\u001b[0m\n",
      "\u001b[1;31mSystemError\u001b[0m: <class 'types.SimpleNamespace'> returned a result with an error set",
      "\nThe above exception was the direct cause of the following exception:\n",
      "\u001b[1;31mSystemError\u001b[0m                               Traceback (most recent call last)",
      "\u001b[1;32m_catboost.pyx\u001b[0m in \u001b[0;36m_catboost._CallbackAfterIteration\u001b[1;34m()\u001b[0m\n",
      "\u001b[1;31mSystemError\u001b[0m: <class 'types.SimpleNamespace'> returned a result with an error set",
      "\nThe above exception was the direct cause of the following exception:\n",
      "\u001b[1;31mSystemError\u001b[0m                               Traceback (most recent call last)",
      "\u001b[1;32m_catboost.pyx\u001b[0m in \u001b[0;36m_catboost._CallbackAfterIteration\u001b[1;34m()\u001b[0m\n",
      "\u001b[1;31mSystemError\u001b[0m: <class 'types.SimpleNamespace'> returned a result with an error set",
      "\nThe above exception was the direct cause of the following exception:\n",
      "\u001b[1;31mSystemError\u001b[0m                               Traceback (most recent call last)",
      "\u001b[1;32m_catboost.pyx\u001b[0m in \u001b[0;36m_catboost._CallbackAfterIteration\u001b[1;34m()\u001b[0m\n",
      "\u001b[1;31mSystemError\u001b[0m: <class 'types.SimpleNamespace'> returned a result with an error set",
      "\nThe above exception was the direct cause of the following exception:\n",
      "\u001b[1;31mSystemError\u001b[0m                               Traceback (most recent call last)",
      "\u001b[1;32m_catboost.pyx\u001b[0m in \u001b[0;36m_catboost._CallbackAfterIteration\u001b[1;34m()\u001b[0m\n",
      "\u001b[1;31mSystemError\u001b[0m: <class 'types.SimpleNamespace'> returned a result with an error set",
      "\nThe above exception was the direct cause of the following exception:\n",
      "\u001b[1;31mSystemError\u001b[0m                               Traceback (most recent call last)",
      "\u001b[1;32m_catboost.pyx\u001b[0m in \u001b[0;36m_catboost._CallbackAfterIteration\u001b[1;34m()\u001b[0m\n",
      "\u001b[1;31mSystemError\u001b[0m: <class 'types.SimpleNamespace'> returned a result with an error set",
      "\nThe above exception was the direct cause of the following exception:\n",
      "\u001b[1;31mSystemError\u001b[0m                               Traceback (most recent call last)",
      "\u001b[1;32m_catboost.pyx\u001b[0m in \u001b[0;36m_catboost._CallbackAfterIteration\u001b[1;34m()\u001b[0m\n",
      "\u001b[1;31mSystemError\u001b[0m: <class 'types.SimpleNamespace'> returned a result with an error set",
      "\nThe above exception was the direct cause of the following exception:\n",
      "\u001b[1;31mSystemError\u001b[0m                               Traceback (most recent call last)",
      "\u001b[1;32m_catboost.pyx\u001b[0m in \u001b[0;36m_catboost._CallbackAfterIteration\u001b[1;34m()\u001b[0m\n",
      "\u001b[1;31mSystemError\u001b[0m: <class 'types.SimpleNamespace'> returned a result with an error set",
      "\nThe above exception was the direct cause of the following exception:\n",
      "\u001b[1;31mSystemError\u001b[0m                               Traceback (most recent call last)",
      "\u001b[1;32m_catboost.pyx\u001b[0m in \u001b[0;36m_catboost._CallbackAfterIteration\u001b[1;34m()\u001b[0m\n",
      "\u001b[1;31mSystemError\u001b[0m: <class 'types.SimpleNamespace'> returned a result with an error set",
      "\nThe above exception was the direct cause of the following exception:\n",
      "\u001b[1;31mSystemError\u001b[0m                               Traceback (most recent call last)",
      "\u001b[1;32m_catboost.pyx\u001b[0m in \u001b[0;36m_catboost._CallbackAfterIteration\u001b[1;34m()\u001b[0m\n",
      "\u001b[1;31mSystemError\u001b[0m: <class 'types.SimpleNamespace'> returned a result with an error set",
      "\nThe above exception was the direct cause of the following exception:\n",
      "\u001b[1;31mSystemError\u001b[0m                               Traceback (most recent call last)",
      "\u001b[1;32m_catboost.pyx\u001b[0m in \u001b[0;36m_catboost._CallbackAfterIteration\u001b[1;34m()\u001b[0m\n",
      "\u001b[1;31mSystemError\u001b[0m: <class 'types.SimpleNamespace'> returned a result with an error set",
      "\nThe above exception was the direct cause of the following exception:\n",
      "\u001b[1;31mSystemError\u001b[0m                               Traceback (most recent call last)",
      "\u001b[1;32m_catboost.pyx\u001b[0m in \u001b[0;36m_catboost._CallbackAfterIteration\u001b[1;34m()\u001b[0m\n",
      "\u001b[1;31mSystemError\u001b[0m: <class 'types.SimpleNamespace'> returned a result with an error set",
      "\nThe above exception was the direct cause of the following exception:\n",
      "\u001b[1;31mSystemError\u001b[0m                               Traceback (most recent call last)",
      "\u001b[1;32m_catboost.pyx\u001b[0m in \u001b[0;36m_catboost._CallbackAfterIteration\u001b[1;34m()\u001b[0m\n",
      "\u001b[1;31mSystemError\u001b[0m: <class 'types.SimpleNamespace'> returned a result with an error set",
      "\nThe above exception was the direct cause of the following exception:\n",
      "\u001b[1;31mSystemError\u001b[0m                               Traceback (most recent call last)",
      "\u001b[1;32m_catboost.pyx\u001b[0m in \u001b[0;36m_catboost._CallbackAfterIteration\u001b[1;34m()\u001b[0m\n",
      "\u001b[1;31mSystemError\u001b[0m: <class 'types.SimpleNamespace'> returned a result with an error set",
      "\nThe above exception was the direct cause of the following exception:\n",
      "\u001b[1;31mSystemError\u001b[0m                               Traceback (most recent call last)",
      "\u001b[1;32m_catboost.pyx\u001b[0m in \u001b[0;36m_catboost._CallbackAfterIteration\u001b[1;34m()\u001b[0m\n",
      "\u001b[1;31mSystemError\u001b[0m: <class 'types.SimpleNamespace'> returned a result with an error set",
      "\nThe above exception was the direct cause of the following exception:\n",
      "\u001b[1;31mSystemError\u001b[0m                               Traceback (most recent call last)",
      "\u001b[1;32m_catboost.pyx\u001b[0m in \u001b[0;36m_catboost._CallbackAfterIteration\u001b[1;34m()\u001b[0m\n",
      "\u001b[1;31mSystemError\u001b[0m: <class 'types.SimpleNamespace'> returned a result with an error set",
      "\nThe above exception was the direct cause of the following exception:\n",
      "\u001b[1;31mSystemError\u001b[0m                               Traceback (most recent call last)",
      "\u001b[1;32m_catboost.pyx\u001b[0m in \u001b[0;36m_catboost._CallbackAfterIteration\u001b[1;34m()\u001b[0m\n",
      "\u001b[1;31mSystemError\u001b[0m: <class 'types.SimpleNamespace'> returned a result with an error set",
      "\nThe above exception was the direct cause of the following exception:\n",
      "\u001b[1;31mSystemError\u001b[0m                               Traceback (most recent call last)",
      "\u001b[1;32m_catboost.pyx\u001b[0m in \u001b[0;36m_catboost._CallbackAfterIteration\u001b[1;34m()\u001b[0m\n",
      "\u001b[1;31mSystemError\u001b[0m: <class 'types.SimpleNamespace'> returned a result with an error set",
      "\nThe above exception was the direct cause of the following exception:\n",
      "\u001b[1;31mSystemError\u001b[0m                               Traceback (most recent call last)",
      "\u001b[1;32m_catboost.pyx\u001b[0m in \u001b[0;36m_catboost._CallbackAfterIteration\u001b[1;34m()\u001b[0m\n",
      "\u001b[1;31mSystemError\u001b[0m: <class 'types.SimpleNamespace'> returned a result with an error set",
      "\nThe above exception was the direct cause of the following exception:\n",
      "\u001b[1;31mSystemError\u001b[0m                               Traceback (most recent call last)",
      "\u001b[1;32m_catboost.pyx\u001b[0m in \u001b[0;36m_catboost._CallbackAfterIteration\u001b[1;34m()\u001b[0m\n",
      "\u001b[1;31mSystemError\u001b[0m: <class 'types.SimpleNamespace'> returned a result with an error set",
      "\nThe above exception was the direct cause of the following exception:\n",
      "\u001b[1;31mSystemError\u001b[0m                               Traceback (most recent call last)",
      "\u001b[1;32m_catboost.pyx\u001b[0m in \u001b[0;36m_catboost._CallbackAfterIteration\u001b[1;34m()\u001b[0m\n",
      "\u001b[1;31mSystemError\u001b[0m: <class 'types.SimpleNamespace'> returned a result with an error set",
      "\nThe above exception was the direct cause of the following exception:\n",
      "\u001b[1;31mSystemError\u001b[0m                               Traceback (most recent call last)",
      "\u001b[1;32m_catboost.pyx\u001b[0m in \u001b[0;36m_catboost._CallbackAfterIteration\u001b[1;34m()\u001b[0m\n",
      "\u001b[1;31mSystemError\u001b[0m: <class 'types.SimpleNamespace'> returned a result with an error set",
      "\nThe above exception was the direct cause of the following exception:\n",
      "\u001b[1;31mSystemError\u001b[0m                               Traceback (most recent call last)",
      "\u001b[1;32m_catboost.pyx\u001b[0m in \u001b[0;36m_catboost._CallbackAfterIteration\u001b[1;34m()\u001b[0m\n",
      "\u001b[1;31mSystemError\u001b[0m: <class 'types.SimpleNamespace'> returned a result with an error set",
      "\nThe above exception was the direct cause of the following exception:\n",
      "\u001b[1;31mSystemError\u001b[0m                               Traceback (most recent call last)",
      "\u001b[1;32m_catboost.pyx\u001b[0m in \u001b[0;36m_catboost._CallbackAfterIteration\u001b[1;34m()\u001b[0m\n",
      "\u001b[1;31mSystemError\u001b[0m: <class 'types.SimpleNamespace'> returned a result with an error set",
      "\nThe above exception was the direct cause of the following exception:\n",
      "\u001b[1;31mSystemError\u001b[0m                               Traceback (most recent call last)",
      "\u001b[1;32m_catboost.pyx\u001b[0m in \u001b[0;36m_catboost._CallbackAfterIteration\u001b[1;34m()\u001b[0m\n",
      "\u001b[1;31mSystemError\u001b[0m: <class 'types.SimpleNamespace'> returned a result with an error set",
      "\nThe above exception was the direct cause of the following exception:\n",
      "\u001b[1;31mSystemError\u001b[0m                               Traceback (most recent call last)",
      "\u001b[1;32m_catboost.pyx\u001b[0m in \u001b[0;36m_catboost._CallbackAfterIteration\u001b[1;34m()\u001b[0m\n",
      "\u001b[1;31mSystemError\u001b[0m: <class 'types.SimpleNamespace'> returned a result with an error set",
      "\nThe above exception was the direct cause of the following exception:\n",
      "\u001b[1;31mSystemError\u001b[0m                               Traceback (most recent call last)",
      "\u001b[1;32m_catboost.pyx\u001b[0m in \u001b[0;36m_catboost._CallbackAfterIteration\u001b[1;34m()\u001b[0m\n",
      "\u001b[1;31mSystemError\u001b[0m: <class 'types.SimpleNamespace'> returned a result with an error set",
      "\nThe above exception was the direct cause of the following exception:\n",
      "\u001b[1;31mSystemError\u001b[0m                               Traceback (most recent call last)",
      "\u001b[1;32m_catboost.pyx\u001b[0m in \u001b[0;36m_catboost._CallbackAfterIteration\u001b[1;34m()\u001b[0m\n",
      "\u001b[1;31mSystemError\u001b[0m: <class 'types.SimpleNamespace'> returned a result with an error set",
      "\nThe above exception was the direct cause of the following exception:\n",
      "\u001b[1;31mSystemError\u001b[0m                               Traceback (most recent call last)",
      "\u001b[1;32m_catboost.pyx\u001b[0m in \u001b[0;36m_catboost._CallbackAfterIteration\u001b[1;34m()\u001b[0m\n",
      "\u001b[1;31mSystemError\u001b[0m: <class 'types.SimpleNamespace'> returned a result with an error set",
      "\nThe above exception was the direct cause of the following exception:\n",
      "\u001b[1;31mSystemError\u001b[0m                               Traceback (most recent call last)",
      "\u001b[1;32m_catboost.pyx\u001b[0m in \u001b[0;36m_catboost._CallbackAfterIteration\u001b[1;34m()\u001b[0m\n",
      "\u001b[1;31mSystemError\u001b[0m: <class 'types.SimpleNamespace'> returned a result with an error set",
      "\nThe above exception was the direct cause of the following exception:\n",
      "\u001b[1;31mSystemError\u001b[0m                               Traceback (most recent call last)",
      "\u001b[1;32m_catboost.pyx\u001b[0m in \u001b[0;36m_catboost._CallbackAfterIteration\u001b[1;34m()\u001b[0m\n",
      "\u001b[1;31mSystemError\u001b[0m: <class 'types.SimpleNamespace'> returned a result with an error set",
      "\nThe above exception was the direct cause of the following exception:\n",
      "\u001b[1;31mSystemError\u001b[0m                               Traceback (most recent call last)",
      "\u001b[1;32m_catboost.pyx\u001b[0m in \u001b[0;36m_catboost._CallbackAfterIteration\u001b[1;34m()\u001b[0m\n",
      "\u001b[1;31mSystemError\u001b[0m: <class 'types.SimpleNamespace'> returned a result with an error set",
      "\nThe above exception was the direct cause of the following exception:\n",
      "\u001b[1;31mSystemError\u001b[0m                               Traceback (most recent call last)",
      "\u001b[1;32m_catboost.pyx\u001b[0m in \u001b[0;36m_catboost._CallbackAfterIteration\u001b[1;34m()\u001b[0m\n",
      "\u001b[1;31mSystemError\u001b[0m: <class 'types.SimpleNamespace'> returned a result with an error set",
      "\nThe above exception was the direct cause of the following exception:\n",
      "\u001b[1;31mSystemError\u001b[0m                               Traceback (most recent call last)",
      "\u001b[1;32m_catboost.pyx\u001b[0m in \u001b[0;36m_catboost._CallbackAfterIteration\u001b[1;34m()\u001b[0m\n",
      "\u001b[1;31mSystemError\u001b[0m: <class 'types.SimpleNamespace'> returned a result with an error set",
      "\nThe above exception was the direct cause of the following exception:\n",
      "\u001b[1;31mSystemError\u001b[0m                               Traceback (most recent call last)",
      "\u001b[1;32m_catboost.pyx\u001b[0m in \u001b[0;36m_catboost._CallbackAfterIteration\u001b[1;34m()\u001b[0m\n",
      "\u001b[1;31mSystemError\u001b[0m: <class 'types.SimpleNamespace'> returned a result with an error set",
      "\nThe above exception was the direct cause of the following exception:\n",
      "\u001b[1;31mSystemError\u001b[0m                               Traceback (most recent call last)",
      "\u001b[1;32m_catboost.pyx\u001b[0m in \u001b[0;36m_catboost._CallbackAfterIteration\u001b[1;34m()\u001b[0m\n",
      "\u001b[1;31mSystemError\u001b[0m: <class 'types.SimpleNamespace'> returned a result with an error set",
      "\nThe above exception was the direct cause of the following exception:\n",
      "\u001b[1;31mSystemError\u001b[0m                               Traceback (most recent call last)",
      "\u001b[1;32m_catboost.pyx\u001b[0m in \u001b[0;36m_catboost._CallbackAfterIteration\u001b[1;34m()\u001b[0m\n",
      "\u001b[1;31mSystemError\u001b[0m: <class 'types.SimpleNamespace'> returned a result with an error set",
      "\nThe above exception was the direct cause of the following exception:\n",
      "\u001b[1;31mSystemError\u001b[0m                               Traceback (most recent call last)",
      "\u001b[1;32m_catboost.pyx\u001b[0m in \u001b[0;36m_catboost._CallbackAfterIteration\u001b[1;34m()\u001b[0m\n",
      "\u001b[1;31mSystemError\u001b[0m: <class 'types.SimpleNamespace'> returned a result with an error set",
      "\nThe above exception was the direct cause of the following exception:\n",
      "\u001b[1;31mSystemError\u001b[0m                               Traceback (most recent call last)",
      "\u001b[1;32m_catboost.pyx\u001b[0m in \u001b[0;36m_catboost._CallbackAfterIteration\u001b[1;34m()\u001b[0m\n",
      "\u001b[1;31mSystemError\u001b[0m: <class 'types.SimpleNamespace'> returned a result with an error set",
      "\nThe above exception was the direct cause of the following exception:\n",
      "\u001b[1;31mSystemError\u001b[0m                               Traceback (most recent call last)",
      "\u001b[1;32m_catboost.pyx\u001b[0m in \u001b[0;36m_catboost._CallbackAfterIteration\u001b[1;34m()\u001b[0m\n",
      "\u001b[1;31mSystemError\u001b[0m: <class 'types.SimpleNamespace'> returned a result with an error set",
      "\nThe above exception was the direct cause of the following exception:\n",
      "\u001b[1;31mSystemError\u001b[0m                               Traceback (most recent call last)",
      "\u001b[1;32m_catboost.pyx\u001b[0m in \u001b[0;36m_catboost._CallbackAfterIteration\u001b[1;34m()\u001b[0m\n",
      "\u001b[1;31mSystemError\u001b[0m: <class 'types.SimpleNamespace'> returned a result with an error set",
      "\nThe above exception was the direct cause of the following exception:\n",
      "\u001b[1;31mSystemError\u001b[0m                               Traceback (most recent call last)",
      "\u001b[1;32m_catboost.pyx\u001b[0m in \u001b[0;36m_catboost._CallbackAfterIteration\u001b[1;34m()\u001b[0m\n",
      "\u001b[1;31mSystemError\u001b[0m: <class 'types.SimpleNamespace'> returned a result with an error set",
      "\nThe above exception was the direct cause of the following exception:\n",
      "\u001b[1;31mSystemError\u001b[0m                               Traceback (most recent call last)",
      "\u001b[1;32m_catboost.pyx\u001b[0m in \u001b[0;36m_catboost._CallbackAfterIteration\u001b[1;34m()\u001b[0m\n",
      "\u001b[1;31mSystemError\u001b[0m: <class 'types.SimpleNamespace'> returned a result with an error set",
      "\nThe above exception was the direct cause of the following exception:\n",
      "\u001b[1;31mSystemError\u001b[0m                               Traceback (most recent call last)",
      "\u001b[1;32m_catboost.pyx\u001b[0m in \u001b[0;36m_catboost._CallbackAfterIteration\u001b[1;34m()\u001b[0m\n",
      "\u001b[1;31mSystemError\u001b[0m: <class 'types.SimpleNamespace'> returned a result with an error set",
      "\nThe above exception was the direct cause of the following exception:\n",
      "\u001b[1;31mSystemError\u001b[0m                               Traceback (most recent call last)",
      "\u001b[1;32m_catboost.pyx\u001b[0m in \u001b[0;36m_catboost._CallbackAfterIteration\u001b[1;34m()\u001b[0m\n",
      "\u001b[1;31mSystemError\u001b[0m: <class 'types.SimpleNamespace'> returned a result with an error set",
      "\nThe above exception was the direct cause of the following exception:\n",
      "\u001b[1;31mSystemError\u001b[0m                               Traceback (most recent call last)",
      "\u001b[1;32m_catboost.pyx\u001b[0m in \u001b[0;36m_catboost._CallbackAfterIteration\u001b[1;34m()\u001b[0m\n",
      "\u001b[1;31mSystemError\u001b[0m: <class 'types.SimpleNamespace'> returned a result with an error set",
      "\nThe above exception was the direct cause of the following exception:\n",
      "\u001b[1;31mSystemError\u001b[0m                               Traceback (most recent call last)",
      "\u001b[1;32m_catboost.pyx\u001b[0m in \u001b[0;36m_catboost._CallbackAfterIteration\u001b[1;34m()\u001b[0m\n",
      "\u001b[1;31mSystemError\u001b[0m: <class 'types.SimpleNamespace'> returned a result with an error set",
      "\nThe above exception was the direct cause of the following exception:\n",
      "\u001b[1;31mSystemError\u001b[0m                               Traceback (most recent call last)",
      "\u001b[1;32m_catboost.pyx\u001b[0m in \u001b[0;36m_catboost._CallbackAfterIteration\u001b[1;34m()\u001b[0m\n",
      "\u001b[1;31mSystemError\u001b[0m: <class 'types.SimpleNamespace'> returned a result with an error set",
      "\nThe above exception was the direct cause of the following exception:\n",
      "\u001b[1;31mSystemError\u001b[0m                               Traceback (most recent call last)",
      "\u001b[1;32m_catboost.pyx\u001b[0m in \u001b[0;36m_catboost._CallbackAfterIteration\u001b[1;34m()\u001b[0m\n",
      "\u001b[1;31mSystemError\u001b[0m: <class 'types.SimpleNamespace'> returned a result with an error set",
      "\nThe above exception was the direct cause of the following exception:\n",
      "\u001b[1;31mSystemError\u001b[0m                               Traceback (most recent call last)",
      "\u001b[1;32m_catboost.pyx\u001b[0m in \u001b[0;36m_catboost._CallbackAfterIteration\u001b[1;34m()\u001b[0m\n",
      "\u001b[1;31mSystemError\u001b[0m: <class 'types.SimpleNamespace'> returned a result with an error set",
      "\nThe above exception was the direct cause of the following exception:\n",
      "\u001b[1;31mSystemError\u001b[0m                               Traceback (most recent call last)",
      "\u001b[1;32m_catboost.pyx\u001b[0m in \u001b[0;36m_catboost._CallbackAfterIteration\u001b[1;34m()\u001b[0m\n",
      "\u001b[1;31mSystemError\u001b[0m: <class 'types.SimpleNamespace'> returned a result with an error set",
      "\nThe above exception was the direct cause of the following exception:\n",
      "\u001b[1;31mSystemError\u001b[0m                               Traceback (most recent call last)",
      "\u001b[1;32m<ipython-input-28-d754437382be>\u001b[0m in \u001b[0;36m<module>\u001b[1;34m\u001b[0m\n\u001b[1;32m----> 1\u001b[1;33m params = performance_report(\n\u001b[0m\u001b[0;32m      2\u001b[0m     \u001b[0mopt\u001b[0m\u001b[1;33m,\u001b[0m\u001b[1;33m\u001b[0m\u001b[1;33m\u001b[0m\u001b[0m\n\u001b[0;32m      3\u001b[0m     \u001b[0mx_train\u001b[0m\u001b[1;33m,\u001b[0m\u001b[1;33m\u001b[0m\u001b[1;33m\u001b[0m\u001b[0m\n\u001b[0;32m      4\u001b[0m     \u001b[0my_train\u001b[0m\u001b[1;33m,\u001b[0m\u001b[1;33m\u001b[0m\u001b[1;33m\u001b[0m\u001b[0m\n\u001b[0;32m      5\u001b[0m     \u001b[1;34m'Bayes CatBoost'\u001b[0m\u001b[1;33m,\u001b[0m\u001b[1;33m\u001b[0m\u001b[1;33m\u001b[0m\u001b[0m\n",
      "\u001b[1;32m<ipython-input-23-2ba9c3f166a1>\u001b[0m in \u001b[0;36mperformance_report\u001b[1;34m(optimizer, x, y, title, callbacks)\u001b[0m\n\u001b[0;32m      6\u001b[0m \u001b[1;33m\u001b[0m\u001b[0m\n\u001b[0;32m      7\u001b[0m     \u001b[1;32mif\u001b[0m \u001b[0mcallbacks\u001b[0m\u001b[1;33m:\u001b[0m\u001b[1;33m\u001b[0m\u001b[1;33m\u001b[0m\u001b[0m\n\u001b[1;32m----> 8\u001b[1;33m         \u001b[0moptimizer\u001b[0m\u001b[1;33m.\u001b[0m\u001b[0mfit\u001b[0m\u001b[1;33m(\u001b[0m\u001b[0mx\u001b[0m\u001b[1;33m,\u001b[0m \u001b[0my\u001b[0m\u001b[1;33m,\u001b[0m \u001b[0mcallbacks\u001b[0m\u001b[1;33m=\u001b[0m\u001b[0mcallbacks\u001b[0m\u001b[1;33m)\u001b[0m\u001b[1;33m\u001b[0m\u001b[1;33m\u001b[0m\u001b[0m\n\u001b[0m\u001b[0;32m      9\u001b[0m     \u001b[1;32melse\u001b[0m\u001b[1;33m:\u001b[0m\u001b[1;33m\u001b[0m\u001b[1;33m\u001b[0m\u001b[0m\n\u001b[0;32m     10\u001b[0m         \u001b[0moptimizer\u001b[0m\u001b[1;33m.\u001b[0m\u001b[0mfit\u001b[0m\u001b[1;33m(\u001b[0m\u001b[0mx\u001b[0m\u001b[1;33m,\u001b[0m \u001b[0my\u001b[0m\u001b[1;33m)\u001b[0m\u001b[1;33m\u001b[0m\u001b[1;33m\u001b[0m\u001b[0m\n",
      "\u001b[1;32m~\\AppData\\Local\\Packages\\PythonSoftwareFoundation.Python.3.9_qbz5n2kfra8p0\\LocalCache\\local-packages\\Python39\\site-packages\\skopt\\searchcv.py\u001b[0m in \u001b[0;36mfit\u001b[1;34m(self, X, y, groups, callback, **fit_params)\u001b[0m\n\u001b[0;32m    464\u001b[0m             \u001b[0mself\u001b[0m\u001b[1;33m.\u001b[0m\u001b[0moptimizer_kwargs_\u001b[0m \u001b[1;33m=\u001b[0m \u001b[0mdict\u001b[0m\u001b[1;33m(\u001b[0m\u001b[0mself\u001b[0m\u001b[1;33m.\u001b[0m\u001b[0moptimizer_kwargs\u001b[0m\u001b[1;33m)\u001b[0m\u001b[1;33m\u001b[0m\u001b[1;33m\u001b[0m\u001b[0m\n\u001b[0;32m    465\u001b[0m \u001b[1;33m\u001b[0m\u001b[0m\n\u001b[1;32m--> 466\u001b[1;33m         \u001b[0msuper\u001b[0m\u001b[1;33m(\u001b[0m\u001b[1;33m)\u001b[0m\u001b[1;33m.\u001b[0m\u001b[0mfit\u001b[0m\u001b[1;33m(\u001b[0m\u001b[0mX\u001b[0m\u001b[1;33m=\u001b[0m\u001b[0mX\u001b[0m\u001b[1;33m,\u001b[0m \u001b[0my\u001b[0m\u001b[1;33m=\u001b[0m\u001b[0my\u001b[0m\u001b[1;33m,\u001b[0m \u001b[0mgroups\u001b[0m\u001b[1;33m=\u001b[0m\u001b[0mgroups\u001b[0m\u001b[1;33m,\u001b[0m \u001b[1;33m**\u001b[0m\u001b[0mfit_params\u001b[0m\u001b[1;33m)\u001b[0m\u001b[1;33m\u001b[0m\u001b[1;33m\u001b[0m\u001b[0m\n\u001b[0m\u001b[0;32m    467\u001b[0m \u001b[1;33m\u001b[0m\u001b[0m\n\u001b[0;32m    468\u001b[0m         \u001b[1;31m# BaseSearchCV never ranked train scores,\u001b[0m\u001b[1;33m\u001b[0m\u001b[1;33m\u001b[0m\u001b[0m\n",
      "\u001b[1;32m~\\AppData\\Local\\Packages\\PythonSoftwareFoundation.Python.3.9_qbz5n2kfra8p0\\LocalCache\\local-packages\\Python39\\site-packages\\sklearn\\model_selection\\_search.py\u001b[0m in \u001b[0;36mfit\u001b[1;34m(self, X, y, groups, **fit_params)\u001b[0m\n\u001b[0;32m    889\u001b[0m                 \u001b[1;32mreturn\u001b[0m \u001b[0mresults\u001b[0m\u001b[1;33m\u001b[0m\u001b[1;33m\u001b[0m\u001b[0m\n\u001b[0;32m    890\u001b[0m \u001b[1;33m\u001b[0m\u001b[0m\n\u001b[1;32m--> 891\u001b[1;33m             \u001b[0mself\u001b[0m\u001b[1;33m.\u001b[0m\u001b[0m_run_search\u001b[0m\u001b[1;33m(\u001b[0m\u001b[0mevaluate_candidates\u001b[0m\u001b[1;33m)\u001b[0m\u001b[1;33m\u001b[0m\u001b[1;33m\u001b[0m\u001b[0m\n\u001b[0m\u001b[0;32m    892\u001b[0m \u001b[1;33m\u001b[0m\u001b[0m\n\u001b[0;32m    893\u001b[0m             \u001b[1;31m# multimetric is determined here because in the case of a callable\u001b[0m\u001b[1;33m\u001b[0m\u001b[1;33m\u001b[0m\u001b[0m\n",
      "\u001b[1;32m~\\AppData\\Local\\Packages\\PythonSoftwareFoundation.Python.3.9_qbz5n2kfra8p0\\LocalCache\\local-packages\\Python39\\site-packages\\skopt\\searchcv.py\u001b[0m in \u001b[0;36m_run_search\u001b[1;34m(self, evaluate_candidates)\u001b[0m\n\u001b[0;32m    510\u001b[0m                 \u001b[0mn_points_adjusted\u001b[0m \u001b[1;33m=\u001b[0m \u001b[0mmin\u001b[0m\u001b[1;33m(\u001b[0m\u001b[0mn_iter\u001b[0m\u001b[1;33m,\u001b[0m \u001b[0mn_points\u001b[0m\u001b[1;33m)\u001b[0m\u001b[1;33m\u001b[0m\u001b[1;33m\u001b[0m\u001b[0m\n\u001b[0;32m    511\u001b[0m \u001b[1;33m\u001b[0m\u001b[0m\n\u001b[1;32m--> 512\u001b[1;33m                 optim_result = self._step(\n\u001b[0m\u001b[0;32m    513\u001b[0m                     \u001b[0msearch_space\u001b[0m\u001b[1;33m,\u001b[0m \u001b[0moptimizer\u001b[0m\u001b[1;33m,\u001b[0m\u001b[1;33m\u001b[0m\u001b[1;33m\u001b[0m\u001b[0m\n\u001b[0;32m    514\u001b[0m                     \u001b[0mevaluate_candidates\u001b[0m\u001b[1;33m,\u001b[0m \u001b[0mn_points\u001b[0m\u001b[1;33m=\u001b[0m\u001b[0mn_points_adjusted\u001b[0m\u001b[1;33m\u001b[0m\u001b[1;33m\u001b[0m\u001b[0m\n",
      "\u001b[1;32m~\\AppData\\Local\\Packages\\PythonSoftwareFoundation.Python.3.9_qbz5n2kfra8p0\\LocalCache\\local-packages\\Python39\\site-packages\\skopt\\searchcv.py\u001b[0m in \u001b[0;36m_step\u001b[1;34m(self, search_space, optimizer, evaluate_candidates, n_points)\u001b[0m\n\u001b[0;32m    406\u001b[0m         \u001b[0mparams_dict\u001b[0m \u001b[1;33m=\u001b[0m \u001b[1;33m[\u001b[0m\u001b[0mpoint_asdict\u001b[0m\u001b[1;33m(\u001b[0m\u001b[0msearch_space\u001b[0m\u001b[1;33m,\u001b[0m \u001b[0mp\u001b[0m\u001b[1;33m)\u001b[0m \u001b[1;32mfor\u001b[0m \u001b[0mp\u001b[0m \u001b[1;32min\u001b[0m \u001b[0mparams\u001b[0m\u001b[1;33m]\u001b[0m\u001b[1;33m\u001b[0m\u001b[1;33m\u001b[0m\u001b[0m\n\u001b[0;32m    407\u001b[0m \u001b[1;33m\u001b[0m\u001b[0m\n\u001b[1;32m--> 408\u001b[1;33m         \u001b[0mall_results\u001b[0m \u001b[1;33m=\u001b[0m \u001b[0mevaluate_candidates\u001b[0m\u001b[1;33m(\u001b[0m\u001b[0mparams_dict\u001b[0m\u001b[1;33m)\u001b[0m\u001b[1;33m\u001b[0m\u001b[1;33m\u001b[0m\u001b[0m\n\u001b[0m\u001b[0;32m    409\u001b[0m         \u001b[1;31m# Feed the point and objective value back into optimizer\u001b[0m\u001b[1;33m\u001b[0m\u001b[1;33m\u001b[0m\u001b[0m\n\u001b[0;32m    410\u001b[0m         \u001b[1;31m# Optimizer minimizes objective, hence provide negative score\u001b[0m\u001b[1;33m\u001b[0m\u001b[1;33m\u001b[0m\u001b[0m\n",
      "\u001b[1;32m~\\AppData\\Local\\Packages\\PythonSoftwareFoundation.Python.3.9_qbz5n2kfra8p0\\LocalCache\\local-packages\\Python39\\site-packages\\sklearn\\model_selection\\_search.py\u001b[0m in \u001b[0;36mevaluate_candidates\u001b[1;34m(candidate_params, cv, more_results)\u001b[0m\n\u001b[0;32m    836\u001b[0m                     )\n\u001b[0;32m    837\u001b[0m \u001b[1;33m\u001b[0m\u001b[0m\n\u001b[1;32m--> 838\u001b[1;33m                 out = parallel(\n\u001b[0m\u001b[0;32m    839\u001b[0m                     delayed(_fit_and_score)(\n\u001b[0;32m    840\u001b[0m                         \u001b[0mclone\u001b[0m\u001b[1;33m(\u001b[0m\u001b[0mbase_estimator\u001b[0m\u001b[1;33m)\u001b[0m\u001b[1;33m,\u001b[0m\u001b[1;33m\u001b[0m\u001b[1;33m\u001b[0m\u001b[0m\n",
      "\u001b[1;32m~\\AppData\\Local\\Packages\\PythonSoftwareFoundation.Python.3.9_qbz5n2kfra8p0\\LocalCache\\local-packages\\Python39\\site-packages\\joblib\\parallel.py\u001b[0m in \u001b[0;36m__call__\u001b[1;34m(self, iterable)\u001b[0m\n\u001b[0;32m   1039\u001b[0m             \u001b[1;31m# remaining jobs.\u001b[0m\u001b[1;33m\u001b[0m\u001b[1;33m\u001b[0m\u001b[0m\n\u001b[0;32m   1040\u001b[0m             \u001b[0mself\u001b[0m\u001b[1;33m.\u001b[0m\u001b[0m_iterating\u001b[0m \u001b[1;33m=\u001b[0m \u001b[1;32mFalse\u001b[0m\u001b[1;33m\u001b[0m\u001b[1;33m\u001b[0m\u001b[0m\n\u001b[1;32m-> 1041\u001b[1;33m             \u001b[1;32mif\u001b[0m \u001b[0mself\u001b[0m\u001b[1;33m.\u001b[0m\u001b[0mdispatch_one_batch\u001b[0m\u001b[1;33m(\u001b[0m\u001b[0miterator\u001b[0m\u001b[1;33m)\u001b[0m\u001b[1;33m:\u001b[0m\u001b[1;33m\u001b[0m\u001b[1;33m\u001b[0m\u001b[0m\n\u001b[0m\u001b[0;32m   1042\u001b[0m                 \u001b[0mself\u001b[0m\u001b[1;33m.\u001b[0m\u001b[0m_iterating\u001b[0m \u001b[1;33m=\u001b[0m \u001b[0mself\u001b[0m\u001b[1;33m.\u001b[0m\u001b[0m_original_iterator\u001b[0m \u001b[1;32mis\u001b[0m \u001b[1;32mnot\u001b[0m \u001b[1;32mNone\u001b[0m\u001b[1;33m\u001b[0m\u001b[1;33m\u001b[0m\u001b[0m\n\u001b[0;32m   1043\u001b[0m \u001b[1;33m\u001b[0m\u001b[0m\n",
      "\u001b[1;32m~\\AppData\\Local\\Packages\\PythonSoftwareFoundation.Python.3.9_qbz5n2kfra8p0\\LocalCache\\local-packages\\Python39\\site-packages\\joblib\\parallel.py\u001b[0m in \u001b[0;36mdispatch_one_batch\u001b[1;34m(self, iterator)\u001b[0m\n\u001b[0;32m    857\u001b[0m                 \u001b[1;32mreturn\u001b[0m \u001b[1;32mFalse\u001b[0m\u001b[1;33m\u001b[0m\u001b[1;33m\u001b[0m\u001b[0m\n\u001b[0;32m    858\u001b[0m             \u001b[1;32melse\u001b[0m\u001b[1;33m:\u001b[0m\u001b[1;33m\u001b[0m\u001b[1;33m\u001b[0m\u001b[0m\n\u001b[1;32m--> 859\u001b[1;33m                 \u001b[0mself\u001b[0m\u001b[1;33m.\u001b[0m\u001b[0m_dispatch\u001b[0m\u001b[1;33m(\u001b[0m\u001b[0mtasks\u001b[0m\u001b[1;33m)\u001b[0m\u001b[1;33m\u001b[0m\u001b[1;33m\u001b[0m\u001b[0m\n\u001b[0m\u001b[0;32m    860\u001b[0m                 \u001b[1;32mreturn\u001b[0m \u001b[1;32mTrue\u001b[0m\u001b[1;33m\u001b[0m\u001b[1;33m\u001b[0m\u001b[0m\n\u001b[0;32m    861\u001b[0m \u001b[1;33m\u001b[0m\u001b[0m\n",
      "\u001b[1;32m~\\AppData\\Local\\Packages\\PythonSoftwareFoundation.Python.3.9_qbz5n2kfra8p0\\LocalCache\\local-packages\\Python39\\site-packages\\joblib\\parallel.py\u001b[0m in \u001b[0;36m_dispatch\u001b[1;34m(self, batch)\u001b[0m\n\u001b[0;32m    775\u001b[0m         \u001b[1;32mwith\u001b[0m \u001b[0mself\u001b[0m\u001b[1;33m.\u001b[0m\u001b[0m_lock\u001b[0m\u001b[1;33m:\u001b[0m\u001b[1;33m\u001b[0m\u001b[1;33m\u001b[0m\u001b[0m\n\u001b[0;32m    776\u001b[0m             \u001b[0mjob_idx\u001b[0m \u001b[1;33m=\u001b[0m \u001b[0mlen\u001b[0m\u001b[1;33m(\u001b[0m\u001b[0mself\u001b[0m\u001b[1;33m.\u001b[0m\u001b[0m_jobs\u001b[0m\u001b[1;33m)\u001b[0m\u001b[1;33m\u001b[0m\u001b[1;33m\u001b[0m\u001b[0m\n\u001b[1;32m--> 777\u001b[1;33m             \u001b[0mjob\u001b[0m \u001b[1;33m=\u001b[0m \u001b[0mself\u001b[0m\u001b[1;33m.\u001b[0m\u001b[0m_backend\u001b[0m\u001b[1;33m.\u001b[0m\u001b[0mapply_async\u001b[0m\u001b[1;33m(\u001b[0m\u001b[0mbatch\u001b[0m\u001b[1;33m,\u001b[0m \u001b[0mcallback\u001b[0m\u001b[1;33m=\u001b[0m\u001b[0mcb\u001b[0m\u001b[1;33m)\u001b[0m\u001b[1;33m\u001b[0m\u001b[1;33m\u001b[0m\u001b[0m\n\u001b[0m\u001b[0;32m    778\u001b[0m             \u001b[1;31m# A job can complete so quickly than its callback is\u001b[0m\u001b[1;33m\u001b[0m\u001b[1;33m\u001b[0m\u001b[0m\n\u001b[0;32m    779\u001b[0m             \u001b[1;31m# called before we get here, causing self._jobs to\u001b[0m\u001b[1;33m\u001b[0m\u001b[1;33m\u001b[0m\u001b[0m\n",
      "\u001b[1;32m~\\AppData\\Local\\Packages\\PythonSoftwareFoundation.Python.3.9_qbz5n2kfra8p0\\LocalCache\\local-packages\\Python39\\site-packages\\joblib\\_parallel_backends.py\u001b[0m in \u001b[0;36mapply_async\u001b[1;34m(self, func, callback)\u001b[0m\n\u001b[0;32m    206\u001b[0m     \u001b[1;32mdef\u001b[0m \u001b[0mapply_async\u001b[0m\u001b[1;33m(\u001b[0m\u001b[0mself\u001b[0m\u001b[1;33m,\u001b[0m \u001b[0mfunc\u001b[0m\u001b[1;33m,\u001b[0m \u001b[0mcallback\u001b[0m\u001b[1;33m=\u001b[0m\u001b[1;32mNone\u001b[0m\u001b[1;33m)\u001b[0m\u001b[1;33m:\u001b[0m\u001b[1;33m\u001b[0m\u001b[1;33m\u001b[0m\u001b[0m\n\u001b[0;32m    207\u001b[0m         \u001b[1;34m\"\"\"Schedule a func to be run\"\"\"\u001b[0m\u001b[1;33m\u001b[0m\u001b[1;33m\u001b[0m\u001b[0m\n\u001b[1;32m--> 208\u001b[1;33m         \u001b[0mresult\u001b[0m \u001b[1;33m=\u001b[0m \u001b[0mImmediateResult\u001b[0m\u001b[1;33m(\u001b[0m\u001b[0mfunc\u001b[0m\u001b[1;33m)\u001b[0m\u001b[1;33m\u001b[0m\u001b[1;33m\u001b[0m\u001b[0m\n\u001b[0m\u001b[0;32m    209\u001b[0m         \u001b[1;32mif\u001b[0m \u001b[0mcallback\u001b[0m\u001b[1;33m:\u001b[0m\u001b[1;33m\u001b[0m\u001b[1;33m\u001b[0m\u001b[0m\n\u001b[0;32m    210\u001b[0m             \u001b[0mcallback\u001b[0m\u001b[1;33m(\u001b[0m\u001b[0mresult\u001b[0m\u001b[1;33m)\u001b[0m\u001b[1;33m\u001b[0m\u001b[1;33m\u001b[0m\u001b[0m\n",
      "\u001b[1;32m~\\AppData\\Local\\Packages\\PythonSoftwareFoundation.Python.3.9_qbz5n2kfra8p0\\LocalCache\\local-packages\\Python39\\site-packages\\joblib\\_parallel_backends.py\u001b[0m in \u001b[0;36m__init__\u001b[1;34m(self, batch)\u001b[0m\n\u001b[0;32m    570\u001b[0m         \u001b[1;31m# Don't delay the application, to avoid keeping the input\u001b[0m\u001b[1;33m\u001b[0m\u001b[1;33m\u001b[0m\u001b[0m\n\u001b[0;32m    571\u001b[0m         \u001b[1;31m# arguments in memory\u001b[0m\u001b[1;33m\u001b[0m\u001b[1;33m\u001b[0m\u001b[0m\n\u001b[1;32m--> 572\u001b[1;33m         \u001b[0mself\u001b[0m\u001b[1;33m.\u001b[0m\u001b[0mresults\u001b[0m \u001b[1;33m=\u001b[0m \u001b[0mbatch\u001b[0m\u001b[1;33m(\u001b[0m\u001b[1;33m)\u001b[0m\u001b[1;33m\u001b[0m\u001b[1;33m\u001b[0m\u001b[0m\n\u001b[0m\u001b[0;32m    573\u001b[0m \u001b[1;33m\u001b[0m\u001b[0m\n\u001b[0;32m    574\u001b[0m     \u001b[1;32mdef\u001b[0m \u001b[0mget\u001b[0m\u001b[1;33m(\u001b[0m\u001b[0mself\u001b[0m\u001b[1;33m)\u001b[0m\u001b[1;33m:\u001b[0m\u001b[1;33m\u001b[0m\u001b[1;33m\u001b[0m\u001b[0m\n",
      "\u001b[1;32m~\\AppData\\Local\\Packages\\PythonSoftwareFoundation.Python.3.9_qbz5n2kfra8p0\\LocalCache\\local-packages\\Python39\\site-packages\\joblib\\parallel.py\u001b[0m in \u001b[0;36m__call__\u001b[1;34m(self)\u001b[0m\n\u001b[0;32m    260\u001b[0m         \u001b[1;31m# change the default number of processes to -1\u001b[0m\u001b[1;33m\u001b[0m\u001b[1;33m\u001b[0m\u001b[0m\n\u001b[0;32m    261\u001b[0m         \u001b[1;32mwith\u001b[0m \u001b[0mparallel_backend\u001b[0m\u001b[1;33m(\u001b[0m\u001b[0mself\u001b[0m\u001b[1;33m.\u001b[0m\u001b[0m_backend\u001b[0m\u001b[1;33m,\u001b[0m \u001b[0mn_jobs\u001b[0m\u001b[1;33m=\u001b[0m\u001b[0mself\u001b[0m\u001b[1;33m.\u001b[0m\u001b[0m_n_jobs\u001b[0m\u001b[1;33m)\u001b[0m\u001b[1;33m:\u001b[0m\u001b[1;33m\u001b[0m\u001b[1;33m\u001b[0m\u001b[0m\n\u001b[1;32m--> 262\u001b[1;33m             return [func(*args, **kwargs)\n\u001b[0m\u001b[0;32m    263\u001b[0m                     for func, args, kwargs in self.items]\n\u001b[0;32m    264\u001b[0m \u001b[1;33m\u001b[0m\u001b[0m\n",
      "\u001b[1;32m~\\AppData\\Local\\Packages\\PythonSoftwareFoundation.Python.3.9_qbz5n2kfra8p0\\LocalCache\\local-packages\\Python39\\site-packages\\joblib\\parallel.py\u001b[0m in \u001b[0;36m<listcomp>\u001b[1;34m(.0)\u001b[0m\n\u001b[0;32m    260\u001b[0m         \u001b[1;31m# change the default number of processes to -1\u001b[0m\u001b[1;33m\u001b[0m\u001b[1;33m\u001b[0m\u001b[0m\n\u001b[0;32m    261\u001b[0m         \u001b[1;32mwith\u001b[0m \u001b[0mparallel_backend\u001b[0m\u001b[1;33m(\u001b[0m\u001b[0mself\u001b[0m\u001b[1;33m.\u001b[0m\u001b[0m_backend\u001b[0m\u001b[1;33m,\u001b[0m \u001b[0mn_jobs\u001b[0m\u001b[1;33m=\u001b[0m\u001b[0mself\u001b[0m\u001b[1;33m.\u001b[0m\u001b[0m_n_jobs\u001b[0m\u001b[1;33m)\u001b[0m\u001b[1;33m:\u001b[0m\u001b[1;33m\u001b[0m\u001b[1;33m\u001b[0m\u001b[0m\n\u001b[1;32m--> 262\u001b[1;33m             return [func(*args, **kwargs)\n\u001b[0m\u001b[0;32m    263\u001b[0m                     for func, args, kwargs in self.items]\n\u001b[0;32m    264\u001b[0m \u001b[1;33m\u001b[0m\u001b[0m\n",
      "\u001b[1;32m~\\AppData\\Local\\Packages\\PythonSoftwareFoundation.Python.3.9_qbz5n2kfra8p0\\LocalCache\\local-packages\\Python39\\site-packages\\sklearn\\utils\\fixes.py\u001b[0m in \u001b[0;36m__call__\u001b[1;34m(self, *args, **kwargs)\u001b[0m\n\u001b[0;32m    214\u001b[0m     \u001b[1;32mdef\u001b[0m \u001b[0m__call__\u001b[0m\u001b[1;33m(\u001b[0m\u001b[0mself\u001b[0m\u001b[1;33m,\u001b[0m \u001b[1;33m*\u001b[0m\u001b[0margs\u001b[0m\u001b[1;33m,\u001b[0m \u001b[1;33m**\u001b[0m\u001b[0mkwargs\u001b[0m\u001b[1;33m)\u001b[0m\u001b[1;33m:\u001b[0m\u001b[1;33m\u001b[0m\u001b[1;33m\u001b[0m\u001b[0m\n\u001b[0;32m    215\u001b[0m         \u001b[1;32mwith\u001b[0m \u001b[0mconfig_context\u001b[0m\u001b[1;33m(\u001b[0m\u001b[1;33m**\u001b[0m\u001b[0mself\u001b[0m\u001b[1;33m.\u001b[0m\u001b[0mconfig\u001b[0m\u001b[1;33m)\u001b[0m\u001b[1;33m:\u001b[0m\u001b[1;33m\u001b[0m\u001b[1;33m\u001b[0m\u001b[0m\n\u001b[1;32m--> 216\u001b[1;33m             \u001b[1;32mreturn\u001b[0m \u001b[0mself\u001b[0m\u001b[1;33m.\u001b[0m\u001b[0mfunction\u001b[0m\u001b[1;33m(\u001b[0m\u001b[1;33m*\u001b[0m\u001b[0margs\u001b[0m\u001b[1;33m,\u001b[0m \u001b[1;33m**\u001b[0m\u001b[0mkwargs\u001b[0m\u001b[1;33m)\u001b[0m\u001b[1;33m\u001b[0m\u001b[1;33m\u001b[0m\u001b[0m\n\u001b[0m\u001b[0;32m    217\u001b[0m \u001b[1;33m\u001b[0m\u001b[0m\n\u001b[0;32m    218\u001b[0m \u001b[1;33m\u001b[0m\u001b[0m\n",
      "\u001b[1;32m~\\AppData\\Local\\Packages\\PythonSoftwareFoundation.Python.3.9_qbz5n2kfra8p0\\LocalCache\\local-packages\\Python39\\site-packages\\sklearn\\model_selection\\_validation.py\u001b[0m in \u001b[0;36m_fit_and_score\u001b[1;34m(estimator, X, y, scorer, train, test, verbose, parameters, fit_params, return_train_score, return_parameters, return_n_test_samples, return_times, return_estimator, split_progress, candidate_progress, error_score)\u001b[0m\n\u001b[0;32m    678\u001b[0m             \u001b[0mestimator\u001b[0m\u001b[1;33m.\u001b[0m\u001b[0mfit\u001b[0m\u001b[1;33m(\u001b[0m\u001b[0mX_train\u001b[0m\u001b[1;33m,\u001b[0m \u001b[1;33m**\u001b[0m\u001b[0mfit_params\u001b[0m\u001b[1;33m)\u001b[0m\u001b[1;33m\u001b[0m\u001b[1;33m\u001b[0m\u001b[0m\n\u001b[0;32m    679\u001b[0m         \u001b[1;32melse\u001b[0m\u001b[1;33m:\u001b[0m\u001b[1;33m\u001b[0m\u001b[1;33m\u001b[0m\u001b[0m\n\u001b[1;32m--> 680\u001b[1;33m             \u001b[0mestimator\u001b[0m\u001b[1;33m.\u001b[0m\u001b[0mfit\u001b[0m\u001b[1;33m(\u001b[0m\u001b[0mX_train\u001b[0m\u001b[1;33m,\u001b[0m \u001b[0my_train\u001b[0m\u001b[1;33m,\u001b[0m \u001b[1;33m**\u001b[0m\u001b[0mfit_params\u001b[0m\u001b[1;33m)\u001b[0m\u001b[1;33m\u001b[0m\u001b[1;33m\u001b[0m\u001b[0m\n\u001b[0m\u001b[0;32m    681\u001b[0m \u001b[1;33m\u001b[0m\u001b[0m\n\u001b[0;32m    682\u001b[0m     \u001b[1;32mexcept\u001b[0m \u001b[0mException\u001b[0m\u001b[1;33m:\u001b[0m\u001b[1;33m\u001b[0m\u001b[1;33m\u001b[0m\u001b[0m\n",
      "\u001b[1;32m~\\AppData\\Local\\Packages\\PythonSoftwareFoundation.Python.3.9_qbz5n2kfra8p0\\LocalCache\\local-packages\\Python39\\site-packages\\catboost\\core.py\u001b[0m in \u001b[0;36mfit\u001b[1;34m(self, X, y, cat_features, text_features, embedding_features, sample_weight, baseline, use_best_model, eval_set, verbose, logging_level, plot, column_description, verbose_eval, metric_period, silent, early_stopping_rounds, save_snapshot, snapshot_file, snapshot_interval, init_model, callbacks, log_cout, log_cerr)\u001b[0m\n\u001b[0;32m   4919\u001b[0m             \u001b[0mCatBoostClassifier\u001b[0m\u001b[1;33m.\u001b[0m\u001b[0m_check_is_compatible_loss\u001b[0m\u001b[1;33m(\u001b[0m\u001b[0mparams\u001b[0m\u001b[1;33m[\u001b[0m\u001b[1;34m'loss_function'\u001b[0m\u001b[1;33m]\u001b[0m\u001b[1;33m)\u001b[0m\u001b[1;33m\u001b[0m\u001b[1;33m\u001b[0m\u001b[0m\n\u001b[0;32m   4920\u001b[0m \u001b[1;33m\u001b[0m\u001b[0m\n\u001b[1;32m-> 4921\u001b[1;33m         self._fit(X, y, cat_features, text_features, embedding_features, None, sample_weight, None, None, None, None, baseline, use_best_model,\n\u001b[0m\u001b[0;32m   4922\u001b[0m                   \u001b[0meval_set\u001b[0m\u001b[1;33m,\u001b[0m \u001b[0mverbose\u001b[0m\u001b[1;33m,\u001b[0m \u001b[0mlogging_level\u001b[0m\u001b[1;33m,\u001b[0m \u001b[0mplot\u001b[0m\u001b[1;33m,\u001b[0m \u001b[0mcolumn_description\u001b[0m\u001b[1;33m,\u001b[0m \u001b[0mverbose_eval\u001b[0m\u001b[1;33m,\u001b[0m \u001b[0mmetric_period\u001b[0m\u001b[1;33m,\u001b[0m\u001b[1;33m\u001b[0m\u001b[1;33m\u001b[0m\u001b[0m\n\u001b[0;32m   4923\u001b[0m                   silent, early_stopping_rounds, save_snapshot, snapshot_file, snapshot_interval, init_model, callbacks, log_cout, log_cerr)\n",
      "\u001b[1;32m~\\AppData\\Local\\Packages\\PythonSoftwareFoundation.Python.3.9_qbz5n2kfra8p0\\LocalCache\\local-packages\\Python39\\site-packages\\catboost\\core.py\u001b[0m in \u001b[0;36m_fit\u001b[1;34m(self, X, y, cat_features, text_features, embedding_features, pairs, sample_weight, group_id, group_weight, subgroup_id, pairs_weight, baseline, use_best_model, eval_set, verbose, logging_level, plot, column_description, verbose_eval, metric_period, silent, early_stopping_rounds, save_snapshot, snapshot_file, snapshot_interval, init_model, callbacks, log_cout, log_cerr)\u001b[0m\n\u001b[0;32m   2190\u001b[0m         \u001b[1;32mwith\u001b[0m \u001b[0mlog_fixup\u001b[0m\u001b[1;33m(\u001b[0m\u001b[0mlog_cout\u001b[0m\u001b[1;33m,\u001b[0m \u001b[0mlog_cerr\u001b[0m\u001b[1;33m)\u001b[0m\u001b[1;33m,\u001b[0m\u001b[0;31m \u001b[0m\u001b[0;31m\\\u001b[0m\u001b[1;33m\u001b[0m\u001b[1;33m\u001b[0m\u001b[0m\n\u001b[0;32m   2191\u001b[0m             \u001b[0mplot_wrapper\u001b[0m\u001b[1;33m(\u001b[0m\u001b[0mplot\u001b[0m\u001b[1;33m,\u001b[0m \u001b[1;33m[\u001b[0m\u001b[0m_get_train_dir\u001b[0m\u001b[1;33m(\u001b[0m\u001b[0mself\u001b[0m\u001b[1;33m.\u001b[0m\u001b[0mget_params\u001b[0m\u001b[1;33m(\u001b[0m\u001b[1;33m)\u001b[0m\u001b[1;33m)\u001b[0m\u001b[1;33m]\u001b[0m\u001b[1;33m)\u001b[0m\u001b[1;33m:\u001b[0m\u001b[1;33m\u001b[0m\u001b[1;33m\u001b[0m\u001b[0m\n\u001b[1;32m-> 2192\u001b[1;33m             self._train(\n\u001b[0m\u001b[0;32m   2193\u001b[0m                 \u001b[0mtrain_pool\u001b[0m\u001b[1;33m,\u001b[0m\u001b[1;33m\u001b[0m\u001b[1;33m\u001b[0m\u001b[0m\n\u001b[0;32m   2194\u001b[0m                 \u001b[0mtrain_params\u001b[0m\u001b[1;33m[\u001b[0m\u001b[1;34m\"eval_sets\"\u001b[0m\u001b[1;33m]\u001b[0m\u001b[1;33m,\u001b[0m\u001b[1;33m\u001b[0m\u001b[1;33m\u001b[0m\u001b[0m\n",
      "\u001b[1;32m~\\AppData\\Local\\Packages\\PythonSoftwareFoundation.Python.3.9_qbz5n2kfra8p0\\LocalCache\\local-packages\\Python39\\site-packages\\catboost\\core.py\u001b[0m in \u001b[0;36m_train\u001b[1;34m(self, train_pool, test_pool, params, allow_clear_pool, init_model)\u001b[0m\n\u001b[0;32m   1617\u001b[0m \u001b[1;33m\u001b[0m\u001b[0m\n\u001b[0;32m   1618\u001b[0m     \u001b[1;32mdef\u001b[0m \u001b[0m_train\u001b[0m\u001b[1;33m(\u001b[0m\u001b[0mself\u001b[0m\u001b[1;33m,\u001b[0m \u001b[0mtrain_pool\u001b[0m\u001b[1;33m,\u001b[0m \u001b[0mtest_pool\u001b[0m\u001b[1;33m,\u001b[0m \u001b[0mparams\u001b[0m\u001b[1;33m,\u001b[0m \u001b[0mallow_clear_pool\u001b[0m\u001b[1;33m,\u001b[0m \u001b[0minit_model\u001b[0m\u001b[1;33m)\u001b[0m\u001b[1;33m:\u001b[0m\u001b[1;33m\u001b[0m\u001b[1;33m\u001b[0m\u001b[0m\n\u001b[1;32m-> 1619\u001b[1;33m         \u001b[0mself\u001b[0m\u001b[1;33m.\u001b[0m\u001b[0m_object\u001b[0m\u001b[1;33m.\u001b[0m\u001b[0m_train\u001b[0m\u001b[1;33m(\u001b[0m\u001b[0mtrain_pool\u001b[0m\u001b[1;33m,\u001b[0m \u001b[0mtest_pool\u001b[0m\u001b[1;33m,\u001b[0m \u001b[0mparams\u001b[0m\u001b[1;33m,\u001b[0m \u001b[0mallow_clear_pool\u001b[0m\u001b[1;33m,\u001b[0m \u001b[0minit_model\u001b[0m\u001b[1;33m.\u001b[0m\u001b[0m_object\u001b[0m \u001b[1;32mif\u001b[0m \u001b[0minit_model\u001b[0m \u001b[1;32melse\u001b[0m \u001b[1;32mNone\u001b[0m\u001b[1;33m)\u001b[0m\u001b[1;33m\u001b[0m\u001b[1;33m\u001b[0m\u001b[0m\n\u001b[0m\u001b[0;32m   1620\u001b[0m         \u001b[0mself\u001b[0m\u001b[1;33m.\u001b[0m\u001b[0m_set_trained_model_attributes\u001b[0m\u001b[1;33m(\u001b[0m\u001b[1;33m)\u001b[0m\u001b[1;33m\u001b[0m\u001b[1;33m\u001b[0m\u001b[0m\n\u001b[0;32m   1621\u001b[0m \u001b[1;33m\u001b[0m\u001b[0m\n",
      "\u001b[1;31mSystemError\u001b[0m: <method '_train' of '_catboost._CatBoost' objects> returned a result with an error set"
     ]
    }
   ],
   "source": [
    "params = performance_report(\n",
    "    opt, \n",
    "    x_train, \n",
    "    y_train, \n",
    "    'Bayes CatBoost', \n",
    "    callbacks=[VerboseCallback(100), DeadlineStopper(60*10)])"
   ]
  },
  {
   "cell_type": "code",
   "execution_count": null,
   "metadata": {},
   "outputs": [],
   "source": [
    "tnd_mdl = CatBoostClassifier(**params, task_type='CPU', od_type='Iter', one_hot_max_size=10)\n",
    "\n",
    "tnd_mdl.fit(x_train, y_train)"
   ]
  },
  {
   "cell_type": "code",
   "execution_count": null,
   "metadata": {},
   "outputs": [],
   "source": [
    "y_pred = tnd_mdl.predict_proba(x_validate)[:, 1]\n",
    "score = np.sqrt(mse(y_validate, y_pred))\n",
    "score"
   ]
  }
 ],
 "metadata": {
  "interpreter": {
   "hash": "69eb92836b941e979072a76c7fcfffe5419cca933cedd02cfafbdfca1a93358c"
  },
  "kernelspec": {
   "display_name": "Python 3.9.10 64-bit",
   "language": "python",
   "name": "python3"
  },
  "language_info": {
   "codemirror_mode": {
    "name": "ipython",
    "version": 3
   },
   "file_extension": ".py",
   "mimetype": "text/x-python",
   "name": "python",
   "nbconvert_exporter": "python",
   "pygments_lexer": "ipython3",
   "version": "3.9.10"
  },
  "orig_nbformat": 4
 },
 "nbformat": 4,
 "nbformat_minor": 2
}
